
/*
 * This is where I put the code to actually place the blocks for structures. I used MCEdit and 
 * the schematic to java converter for it. It gets painful though, as the tools always do it just
 * a little bit wrong and I have to change one letter fifty times... But anyways the tools are
 * useful and you should use them
 */

package com.pdogmuncher.zombieapocalypse.generation;

import java.util.Random;

import com.pdogmuncher.zombieapocalypse.ZombieApocalypse;
import com.pdogmuncher.zombieapocalypse.generation.BronzeGenerator.CityBuildingType;
import com.pdogmuncher.zombieapocalypse.items.ItemBackpack;
import com.pdogmuncher.zombieapocalypse.items.ItemBackpack.FillType;

import net.minecraft.block.Block;
import net.minecraft.block.BlockDoor;
import net.minecraft.block.BlockLadder;
import net.minecraft.block.BlockSign;
import net.minecraft.block.BlockWallSign;
import net.minecraft.block.state.IBlockState;
import net.minecraft.entity.item.EntityEnderCrystal;
import net.minecraft.entity.passive.EntityCow;
import net.minecraft.init.Blocks;
import net.minecraft.init.Items;
import net.minecraft.item.ItemStack;
import net.minecraft.tileentity.TileEntityChest;
import net.minecraft.tileentity.TileEntityFurnace;
import net.minecraft.tileentity.TileEntitySign;
import net.minecraft.util.BlockPos;
import net.minecraft.util.ChatComponentText;
import net.minecraft.util.EnumFacing;
import net.minecraft.world.World;
import net.minecraft.world.chunk.IChunkProvider;
import net.minecraftforge.fml.common.IWorldGenerator;

public class City
{	
	public void setBlock(World world, int x, int y, int z, Block block, int metadata)
	{
		Block b1 = world.getBlockState(new BlockPos(x, y, z)).getBlock();

		world.setBlockState(new BlockPos(x, y, z), block.getDefaultState());
		
	}
	
	public boolean generate(World world, Random rand, int i, int j, int k) {
		
		k = k - 10;
		i = i - 10;
		

		this.setBlock(world, i + 0, j + 0, k + 0, Blocks.grass, 0);
		this.setBlock(world, i + 0, j + 0, k + 1, Blocks.grass, 0);
		this.setBlock(world, i + 0, j + 0, k + 2, Blocks.grass, 0);
		this.setBlock(world, i + 0, j + 0, k + 3, Blocks.dirt, 0);
		this.setBlock(world, i + 0, j + 0, k + 4, Blocks.dirt, 0);
		this.setBlock(world, i + 0, j + 0, k + 5, Blocks.dirt, 0);
		this.setBlock(world, i + 0, j + 0, k + 6, Blocks.dirt, 0);
		this.setBlock(world, i + 0, j + 0, k + 7, Blocks.grass, 0);
		this.setBlock(world, i + 0, j + 0, k + 8, Blocks.grass, 0);
		this.setBlock(world, i + 0, j + 0, k + 9, Blocks.grass, 0);
		this.setBlock(world, i + 0, j + 1, k + 3, Blocks.obsidian, 0);
		this.setBlock(world, i + 0, j + 1, k + 4, Blocks.obsidian, 0);
		this.setBlock(world, i + 0, j + 1, k + 5, Blocks.obsidian, 0);
		this.setBlock(world, i + 0, j + 1, k + 6, Blocks.obsidian, 0);
		this.setBlock(world, i + 0, j + 2, k + 3, Blocks.glowstone, 0);
		this.setBlock(world, i + 0, j + 2, k + 4, Blocks.obsidian, 0);
		this.setBlock(world, i + 0, j + 2, k + 5, Blocks.obsidian, 0);
		this.setBlock(world, i + 0, j + 2, k + 6, Blocks.glowstone, 0);
		this.setBlock(world, i + 0, j + 3, k + 3, Blocks.glowstone, 0);
		this.setBlock(world, i + 0, j + 3, k + 4, Blocks.obsidian, 0);
		this.setBlock(world, i + 0, j + 3, k + 5, Blocks.obsidian, 0);
		this.setBlock(world, i + 0, j + 3, k + 6, Blocks.glowstone, 0);
		this.setBlock(world, i + 0, j + 4, k + 3, Blocks.glowstone, 0);
		this.setBlock(world, i + 0, j + 4, k + 4, Blocks.obsidian, 0);
		this.setBlock(world, i + 0, j + 4, k + 5, Blocks.obsidian, 0);
		this.setBlock(world, i + 0, j + 4, k + 6, Blocks.glowstone, 0);
		this.setBlock(world, i + 0, j + 5, k + 3, Blocks.glowstone, 0);
		this.setBlock(world, i + 0, j + 5, k + 4, Blocks.obsidian, 0);
		this.setBlock(world, i + 0, j + 5, k + 5, Blocks.obsidian, 0);
		this.setBlock(world, i + 0, j + 5, k + 6, Blocks.glowstone, 0);
		this.setBlock(world, i + 1, j + 0, k + 0, Blocks.grass, 0);
		this.setBlock(world, i + 1, j + 0, k + 1, Blocks.grass, 0);
		this.setBlock(world, i + 1, j + 0, k + 2, Blocks.dirt, 0);
		this.setBlock(world, i + 1, j + 0, k + 3, Blocks.dirt, 0);
		this.setBlock(world, i + 1, j + 0, k + 4, Blocks.dirt, 0);
		this.setBlock(world, i + 1, j + 0, k + 5, Blocks.dirt, 0);
		this.setBlock(world, i + 1, j + 0, k + 6, Blocks.dirt, 0);
		this.setBlock(world, i + 1, j + 0, k + 7, Blocks.dirt, 0);
		this.setBlock(world, i + 1, j + 0, k + 8, Blocks.grass, 0);
		this.setBlock(world, i + 1, j + 0, k + 9, Blocks.grass, 0);
		this.setBlock(world, i + 1, j + 1, k + 2, Blocks.obsidian, 0);
		this.setBlock(world, i + 1, j + 1, k + 3, Blocks.obsidian, 0);
		this.setBlock(world, i + 1, j + 1, k + 4, Blocks.obsidian, 0);
		this.setBlock(world, i + 1, j + 1, k + 5, Blocks.obsidian, 0);
		this.setBlock(world, i + 1, j + 1, k + 6, Blocks.obsidian, 0);
		this.setBlock(world, i + 1, j + 1, k + 7, Blocks.obsidian, 0);
		this.setBlock(world, i + 1, j + 2, k + 2, Blocks.obsidian, 0);
		this.setBlock(world, i + 1, j + 2, k + 4, Blocks.chest, 5);
		TileEntityChest chest = (TileEntityChest)world.getTileEntity(new BlockPos(i + 1, j + 2, k + 4));
		chest.setInventorySlotContents(0, new ItemStack(ZombieApocalypse.cosmoStaff));
		this.setBlock(world, i + 1, j + 2, k + 5, Blocks.chest, 5);
		this.setBlock(world, i + 1, j + 2, k + 7, Blocks.obsidian, 0);
		this.setBlock(world, i + 1, j + 3, k + 2, Blocks.obsidian, 0);
		this.setBlock(world, i + 1, j + 3, k + 7, Blocks.obsidian, 0);
		this.setBlock(world, i + 1, j + 4, k + 2, Blocks.obsidian, 0);
		this.setBlock(world, i + 1, j + 4, k + 7, Blocks.obsidian, 0);
		this.setBlock(world, i + 1, j + 5, k + 2, Blocks.obsidian, 0);
		this.setBlock(world, i + 1, j + 5, k + 7, Blocks.obsidian, 0);
		this.setBlock(world, i + 1, j + 6, k + 3, Blocks.obsidian, 0);
		this.setBlock(world, i + 1, j + 6, k + 4, Blocks.obsidian, 0);
		this.setBlock(world, i + 1, j + 6, k + 5, Blocks.obsidian, 0);
		this.setBlock(world, i + 1, j + 6, k + 6, Blocks.obsidian, 0);
		this.setBlock(world, i + 2, j + 0, k + 0, Blocks.grass, 0);
		this.setBlock(world, i + 2, j + 0, k + 1, Blocks.dirt, 0);
		this.setBlock(world, i + 2, j + 0, k + 2, Blocks.dirt, 0);
		this.setBlock(world, i + 2, j + 0, k + 3, Blocks.dirt, 0);
		this.setBlock(world, i + 2, j + 0, k + 4, Blocks.dirt, 0);
		this.setBlock(world, i + 2, j + 0, k + 5, Blocks.dirt, 0);
		this.setBlock(world, i + 2, j + 0, k + 6, Blocks.dirt, 0);
		this.setBlock(world, i + 2, j + 0, k + 7, Blocks.dirt, 0);
		this.setBlock(world, i + 2, j + 0, k + 8, Blocks.dirt, 0);
		this.setBlock(world, i + 2, j + 0, k + 9, Blocks.grass, 0);
		this.setBlock(world, i + 2, j + 1, k + 1, Blocks.obsidian, 0);
		this.setBlock(world, i + 2, j + 1, k + 2, Blocks.obsidian, 0);
		this.setBlock(world, i + 2, j + 1, k + 3, Blocks.obsidian, 0);
		this.setBlock(world, i + 2, j + 1, k + 4, Blocks.obsidian, 0);
		this.setBlock(world, i + 2, j + 1, k + 5, Blocks.obsidian, 0);
		this.setBlock(world, i + 2, j + 1, k + 6, Blocks.obsidian, 0);
		this.setBlock(world, i + 2, j + 1, k + 7, Blocks.obsidian, 0);
		this.setBlock(world, i + 2, j + 1, k + 8, Blocks.obsidian, 0);
		this.setBlock(world, i + 2, j + 2, k + 1, Blocks.obsidian, 0);
		this.setBlock(world, i + 2, j + 2, k + 8, Blocks.obsidian, 0);
		this.setBlock(world, i + 2, j + 3, k + 1, Blocks.obsidian, 0);
		this.setBlock(world, i + 2, j + 3, k + 8, Blocks.obsidian, 0);
		this.setBlock(world, i + 2, j + 4, k + 1, Blocks.obsidian, 0);
		this.setBlock(world, i + 2, j + 4, k + 8, Blocks.obsidian, 0);
		this.setBlock(world, i + 2, j + 5, k + 1, Blocks.obsidian, 0);
		this.setBlock(world, i + 2, j + 5, k + 8, Blocks.obsidian, 0);
		this.setBlock(world, i + 2, j + 6, k + 2, Blocks.obsidian, 0);
		this.setBlock(world, i + 2, j + 6, k + 3, Blocks.obsidian, 0);
		this.setBlock(world, i + 2, j + 6, k + 6, Blocks.obsidian, 0);
		this.setBlock(world, i + 2, j + 6, k + 7, Blocks.obsidian, 0);
		this.setBlock(world, i + 2, j + 7, k + 4, Blocks.obsidian, 0);
		this.setBlock(world, i + 2, j + 7, k + 5, Blocks.obsidian, 0);
		this.setBlock(world, i + 3, j + 0, k + 0, Blocks.dirt, 0);
		this.setBlock(world, i + 3, j + 0, k + 1, Blocks.dirt, 0);
		this.setBlock(world, i + 3, j + 0, k + 2, Blocks.dirt, 0);
		this.setBlock(world, i + 3, j + 0, k + 3, Blocks.dirt, 0);
		this.setBlock(world, i + 3, j + 0, k + 4, Blocks.dirt, 0);
		this.setBlock(world, i + 3, j + 0, k + 5, Blocks.dirt, 0);
		this.setBlock(world, i + 3, j + 0, k + 6, Blocks.dirt, 0);
		this.setBlock(world, i + 3, j + 0, k + 7, Blocks.dirt, 0);
		this.setBlock(world, i + 3, j + 0, k + 8, Blocks.dirt, 0);
		this.setBlock(world, i + 3, j + 0, k + 9, Blocks.dirt, 0);
		this.setBlock(world, i + 3, j + 1, k + 0, Blocks.obsidian, 0);
		this.setBlock(world, i + 3, j + 1, k + 1, Blocks.obsidian, 0);
		this.setBlock(world, i + 3, j + 1, k + 2, Blocks.obsidian, 0);
		this.setBlock(world, i + 3, j + 1, k + 3, Blocks.obsidian, 0);
		this.setBlock(world, i + 3, j + 1, k + 4, Blocks.obsidian, 0);
		this.setBlock(world, i + 3, j + 1, k + 5, Blocks.obsidian, 0);
		this.setBlock(world, i + 3, j + 1, k + 6, Blocks.obsidian, 0);
		this.setBlock(world, i + 3, j + 1, k + 7, Blocks.obsidian, 0);
		this.setBlock(world, i + 3, j + 1, k + 8, Blocks.obsidian, 0);
		this.setBlock(world, i + 3, j + 1, k + 9, Blocks.obsidian, 0);
		this.setBlock(world, i + 3, j + 2, k + 0, Blocks.glowstone, 0);
		this.setBlock(world, i + 3, j + 2, k + 9, Blocks.glowstone, 0);
		this.setBlock(world, i + 3, j + 3, k + 0, Blocks.glowstone, 0);
		this.setBlock(world, i + 3, j + 3, k + 9, Blocks.glowstone, 0);
		this.setBlock(world, i + 3, j + 4, k + 0, Blocks.glowstone, 0);
		this.setBlock(world, i + 3, j + 4, k + 9, Blocks.glowstone, 0);
		this.setBlock(world, i + 3, j + 5, k + 0, Blocks.glowstone, 0);
		this.setBlock(world, i + 3, j + 5, k + 9, Blocks.glowstone, 0);
		this.setBlock(world, i + 3, j + 6, k + 1, Blocks.obsidian, 0);
		this.setBlock(world, i + 3, j + 6, k + 2, Blocks.obsidian, 0);
		this.setBlock(world, i + 3, j + 6, k + 7, Blocks.obsidian, 0);
		this.setBlock(world, i + 3, j + 6, k + 8, Blocks.obsidian, 0);
		this.setBlock(world, i + 3, j + 7, k + 3, Blocks.obsidian, 0);
		this.setBlock(world, i + 3, j + 7, k + 6, Blocks.obsidian, 0);
		this.setBlock(world, i + 3, j + 8, k + 4, Blocks.obsidian, 0);
		this.setBlock(world, i + 3, j + 8, k + 5, Blocks.obsidian, 0);
		this.setBlock(world, i + 4, j + 0, k + 0, Blocks.dirt, 0);
		this.setBlock(world, i + 4, j + 0, k + 1, Blocks.dirt, 0);
		this.setBlock(world, i + 4, j + 0, k + 2, Blocks.dirt, 0);
		this.setBlock(world, i + 4, j + 0, k + 3, Blocks.dirt, 0);
		this.setBlock(world, i + 4, j + 0, k + 4, Blocks.dirt, 0);
		this.setBlock(world, i + 4, j + 0, k + 5, Blocks.dirt, 0);
		this.setBlock(world, i + 4, j + 0, k + 6, Blocks.dirt, 0);
		this.setBlock(world, i + 4, j + 0, k + 7, Blocks.dirt, 0);
		this.setBlock(world, i + 4, j + 0, k + 8, Blocks.dirt, 0);
		this.setBlock(world, i + 4, j + 0, k + 9, Blocks.dirt, 0);
		this.setBlock(world, i + 4, j + 1, k + 0, Blocks.obsidian, 0);
		this.setBlock(world, i + 4, j + 1, k + 1, Blocks.obsidian, 0);
		this.setBlock(world, i + 4, j + 1, k + 2, Blocks.obsidian, 0);
		this.setBlock(world, i + 4, j + 1, k + 3, Blocks.obsidian, 0);
		this.setBlock(world, i + 4, j + 1, k + 4, Blocks.obsidian, 0);
		this.setBlock(world, i + 4, j + 1, k + 5, Blocks.obsidian, 0);
		this.setBlock(world, i + 4, j + 1, k + 6, Blocks.obsidian, 0);
		this.setBlock(world, i + 4, j + 1, k + 7, Blocks.obsidian, 0);
		this.setBlock(world, i + 4, j + 1, k + 8, Blocks.obsidian, 0);
		this.setBlock(world, i + 4, j + 1, k + 9, Blocks.obsidian, 0);
		this.setBlock(world, i + 4, j + 2, k + 0, Blocks.obsidian, 0);
		this.setBlock(world, i + 4, j + 2, k + 9, Blocks.obsidian, 0);
		this.setBlock(world, i + 4, j + 3, k + 0, Blocks.obsidian, 0);
		this.setBlock(world, i + 4, j + 3, k + 9, Blocks.obsidian, 0);
		this.setBlock(world, i + 4, j + 4, k + 0, Blocks.obsidian, 0);
		this.setBlock(world, i + 4, j + 4, k + 9, Blocks.obsidian, 0);
		this.setBlock(world, i + 4, j + 5, k + 0, Blocks.obsidian, 0);
		this.setBlock(world, i + 4, j + 5, k + 9, Blocks.obsidian, 0);
		this.setBlock(world, i + 4, j + 6, k + 1, Blocks.obsidian, 0);
		this.setBlock(world, i + 4, j + 6, k + 8, Blocks.obsidian, 0);
		this.setBlock(world, i + 4, j + 7, k + 2, Blocks.obsidian, 0);
		this.setBlock(world, i + 4, j + 7, k + 7, Blocks.obsidian, 0);
		this.setBlock(world, i + 4, j + 8, k + 3, Blocks.obsidian, 0);
		this.setBlock(world, i + 4, j + 8, k + 4, Blocks.obsidian, 0);
		this.setBlock(world, i + 4, j + 8, k + 5, Blocks.obsidian, 0);
		this.setBlock(world, i + 4, j + 8, k + 6, Blocks.obsidian, 0);
		this.setBlock(world, i + 5, j + 0, k + 0, Blocks.dirt, 0);
		this.setBlock(world, i + 5, j + 0, k + 1, Blocks.dirt, 0);
		this.setBlock(world, i + 5, j + 0, k + 2, Blocks.dirt, 0);
		this.setBlock(world, i + 5, j + 0, k + 3, Blocks.dirt, 0);
		this.setBlock(world, i + 5, j + 0, k + 4, Blocks.dirt, 0);
		this.setBlock(world, i + 5, j + 0, k + 5, Blocks.dirt, 0);
		this.setBlock(world, i + 5, j + 0, k + 6, Blocks.dirt, 0);
		this.setBlock(world, i + 5, j + 0, k + 7, Blocks.dirt, 0);
		this.setBlock(world, i + 5, j + 0, k + 8, Blocks.dirt, 0);
		this.setBlock(world, i + 5, j + 0, k + 9, Blocks.dirt, 0);
		this.setBlock(world, i + 5, j + 1, k + 0, Blocks.obsidian, 0);
		this.setBlock(world, i + 5, j + 1, k + 1, Blocks.obsidian, 0);
		this.setBlock(world, i + 5, j + 1, k + 2, Blocks.obsidian, 0);
		this.setBlock(world, i + 5, j + 1, k + 3, Blocks.obsidian, 0);
		this.setBlock(world, i + 5, j + 1, k + 4, Blocks.obsidian, 0);
		this.setBlock(world, i + 5, j + 1, k + 5, Blocks.obsidian, 0);
		this.setBlock(world, i + 5, j + 1, k + 6, Blocks.obsidian, 0);
		this.setBlock(world, i + 5, j + 1, k + 7, Blocks.obsidian, 0);
		this.setBlock(world, i + 5, j + 1, k + 8, Blocks.obsidian, 0);
		this.setBlock(world, i + 5, j + 1, k + 9, Blocks.obsidian, 0);
		this.setBlock(world, i + 5, j + 2, k + 0, Blocks.obsidian, 0);
		this.setBlock(world, i + 5, j + 2, k + 9, Blocks.obsidian, 0);
		this.setBlock(world, i + 5, j + 3, k + 0, Blocks.obsidian, 0);
		this.setBlock(world, i + 5, j + 3, k + 9, Blocks.obsidian, 0);
		this.setBlock(world, i + 5, j + 4, k + 0, Blocks.obsidian, 0);
		this.setBlock(world, i + 5, j + 4, k + 9, Blocks.obsidian, 0);
		this.setBlock(world, i + 5, j + 5, k + 0, Blocks.obsidian, 0);
		this.setBlock(world, i + 5, j + 5, k + 9, Blocks.obsidian, 0);
		this.setBlock(world, i + 5, j + 6, k + 1, Blocks.obsidian, 0);
		this.setBlock(world, i + 5, j + 6, k + 8, Blocks.obsidian, 0);
		this.setBlock(world, i + 5, j + 7, k + 2, Blocks.obsidian, 0);
		this.setBlock(world, i + 5, j + 7, k + 7, Blocks.obsidian, 0);
		this.setBlock(world, i + 5, j + 8, k + 3, Blocks.obsidian, 0);
		this.setBlock(world, i + 5, j + 8, k + 4, Blocks.obsidian, 0);
		this.setBlock(world, i + 5, j + 8, k + 5, Blocks.obsidian, 0);
		this.setBlock(world, i + 5, j + 8, k + 6, Blocks.obsidian, 0);
		this.setBlock(world, i + 6, j + 0, k + 0, Blocks.dirt, 0);
		this.setBlock(world, i + 6, j + 0, k + 1, Blocks.dirt, 0);
		this.setBlock(world, i + 6, j + 0, k + 2, Blocks.dirt, 0);
		this.setBlock(world, i + 6, j + 0, k + 3, Blocks.dirt, 0);
		this.setBlock(world, i + 6, j + 0, k + 4, Blocks.dirt, 0);
		this.setBlock(world, i + 6, j + 0, k + 5, Blocks.dirt, 0);
		this.setBlock(world, i + 6, j + 0, k + 6, Blocks.dirt, 0);
		this.setBlock(world, i + 6, j + 0, k + 7, Blocks.dirt, 0);
		this.setBlock(world, i + 6, j + 0, k + 8, Blocks.dirt, 0);
		this.setBlock(world, i + 6, j + 0, k + 9, Blocks.dirt, 0);
		this.setBlock(world, i + 6, j + 1, k + 0, Blocks.obsidian, 0);
		this.setBlock(world, i + 6, j + 1, k + 1, Blocks.obsidian, 0);
		this.setBlock(world, i + 6, j + 1, k + 2, Blocks.obsidian, 0);
		this.setBlock(world, i + 6, j + 1, k + 3, Blocks.obsidian, 0);
		this.setBlock(world, i + 6, j + 1, k + 4, Blocks.obsidian, 0);
		this.setBlock(world, i + 6, j + 1, k + 5, Blocks.obsidian, 0);
		this.setBlock(world, i + 6, j + 1, k + 6, Blocks.obsidian, 0);
		this.setBlock(world, i + 6, j + 1, k + 7, Blocks.obsidian, 0);
		this.setBlock(world, i + 6, j + 1, k + 8, Blocks.obsidian, 0);
		this.setBlock(world, i + 6, j + 1, k + 9, Blocks.obsidian, 0);
		this.setBlock(world, i + 6, j + 2, k + 0, Blocks.glowstone, 0);
		this.setBlock(world, i + 6, j + 2, k + 9, Blocks.glowstone, 0);
		this.setBlock(world, i + 6, j + 3, k + 0, Blocks.glowstone, 0);
		this.setBlock(world, i + 6, j + 3, k + 9, Blocks.glowstone, 0);
		this.setBlock(world, i + 6, j + 4, k + 0, Blocks.glowstone, 0);
		this.setBlock(world, i + 6, j + 4, k + 9, Blocks.glowstone, 0);
		this.setBlock(world, i + 6, j + 5, k + 0, Blocks.glowstone, 0);
		this.setBlock(world, i + 6, j + 5, k + 9, Blocks.glowstone, 0);
		this.setBlock(world, i + 6, j + 6, k + 1, Blocks.obsidian, 0);
		this.setBlock(world, i + 6, j + 6, k + 2, Blocks.obsidian, 0);
		this.setBlock(world, i + 6, j + 6, k + 7, Blocks.obsidian, 0);
		this.setBlock(world, i + 6, j + 6, k + 8, Blocks.obsidian, 0);
		this.setBlock(world, i + 6, j + 7, k + 3, Blocks.obsidian, 0);
		this.setBlock(world, i + 6, j + 7, k + 6, Blocks.obsidian, 0);
		this.setBlock(world, i + 6, j + 8, k + 4, Blocks.obsidian, 0);
		this.setBlock(world, i + 6, j + 8, k + 5, Blocks.obsidian, 0);
		this.setBlock(world, i + 7, j + 0, k + 0, Blocks.grass, 0);
		this.setBlock(world, i + 7, j + 0, k + 1, Blocks.dirt, 0);
		this.setBlock(world, i + 7, j + 0, k + 2, Blocks.dirt, 0);
		this.setBlock(world, i + 7, j + 0, k + 3, Blocks.dirt, 0);
		this.setBlock(world, i + 7, j + 0, k + 4, Blocks.dirt, 0);
		this.setBlock(world, i + 7, j + 0, k + 5, Blocks.dirt, 0);
		this.setBlock(world, i + 7, j + 0, k + 6, Blocks.dirt, 0);
		this.setBlock(world, i + 7, j + 0, k + 7, Blocks.dirt, 0);
		this.setBlock(world, i + 7, j + 0, k + 8, Blocks.dirt, 0);
		this.setBlock(world, i + 7, j + 0, k + 9, Blocks.grass, 0);
		this.setBlock(world, i + 7, j + 1, k + 1, Blocks.obsidian, 0);
		this.setBlock(world, i + 7, j + 1, k + 2, Blocks.obsidian, 0);
		this.setBlock(world, i + 7, j + 1, k + 3, Blocks.obsidian, 0);
		this.setBlock(world, i + 7, j + 1, k + 4, Blocks.obsidian, 0);
		this.setBlock(world, i + 7, j + 1, k + 5, Blocks.obsidian, 0);
		this.setBlock(world, i + 7, j + 1, k + 6, Blocks.obsidian, 0);
		this.setBlock(world, i + 7, j + 1, k + 7, Blocks.obsidian, 0);
		this.setBlock(world, i + 7, j + 1, k + 8, Blocks.obsidian, 0);
		this.setBlock(world, i + 7, j + 2, k + 1, Blocks.obsidian, 0);
		this.setBlock(world, i + 7, j + 2, k + 8, Blocks.obsidian, 0);
		this.setBlock(world, i + 7, j + 3, k + 1, Blocks.obsidian, 0);
		this.setBlock(world, i + 7, j + 3, k + 8, Blocks.obsidian, 0);
		this.setBlock(world, i + 7, j + 4, k + 1, Blocks.obsidian, 0);
		this.setBlock(world, i + 7, j + 4, k + 8, Blocks.obsidian, 0);
		this.setBlock(world, i + 7, j + 5, k + 1, Blocks.obsidian, 0);
		this.setBlock(world, i + 7, j + 5, k + 8, Blocks.obsidian, 0);
		this.setBlock(world, i + 7, j + 6, k + 2, Blocks.obsidian, 0);
		this.setBlock(world, i + 7, j + 6, k + 3, Blocks.obsidian, 0);
		this.setBlock(world, i + 7, j + 6, k + 6, Blocks.obsidian, 0);
		this.setBlock(world, i + 7, j + 6, k + 7, Blocks.obsidian, 0);
		this.setBlock(world, i + 7, j + 7, k + 4, Blocks.obsidian, 0);
		this.setBlock(world, i + 7, j + 7, k + 5, Blocks.obsidian, 0);
		this.setBlock(world, i + 8, j + 0, k + 0, Blocks.grass, 0);
		this.setBlock(world, i + 8, j + 0, k + 1, Blocks.grass, 0);
		this.setBlock(world, i + 8, j + 0, k + 2, Blocks.dirt, 0);
		this.setBlock(world, i + 8, j + 0, k + 3, Blocks.dirt, 0);
		this.setBlock(world, i + 8, j + 0, k + 4, Blocks.dirt, 0);
		this.setBlock(world, i + 8, j + 0, k + 5, Blocks.dirt, 0);
		this.setBlock(world, i + 8, j + 0, k + 6, Blocks.dirt, 0);
		this.setBlock(world, i + 8, j + 0, k + 7, Blocks.dirt, 0);
		this.setBlock(world, i + 8, j + 0, k + 8, Blocks.grass, 0);
		this.setBlock(world, i + 8, j + 0, k + 9, Blocks.grass, 0);
		this.setBlock(world, i + 8, j + 1, k + 2, Blocks.obsidian, 0);
		this.setBlock(world, i + 8, j + 1, k + 3, Blocks.obsidian, 0);
		this.setBlock(world, i + 8, j + 1, k + 4, Blocks.obsidian, 0);
		this.setBlock(world, i + 8, j + 1, k + 5, Blocks.obsidian, 0);
		this.setBlock(world, i + 8, j + 1, k + 6, Blocks.obsidian, 0);
		this.setBlock(world, i + 8, j + 1, k + 7, Blocks.obsidian, 0);
		this.setBlock(world, i + 8, j + 2, k + 2, Blocks.obsidian, 0);
		this.setBlock(world, i + 8, j + 2, k + 7, Blocks.obsidian, 0);
		this.setBlock(world, i + 8, j + 3, k + 2, Blocks.obsidian, 0);
		this.setBlock(world, i + 8, j + 3, k + 7, Blocks.obsidian, 0);
		this.setBlock(world, i + 8, j + 4, k + 2, Blocks.obsidian, 0);
		this.setBlock(world, i + 8, j + 4, k + 7, Blocks.obsidian, 0);
		this.setBlock(world, i + 8, j + 5, k + 2, Blocks.obsidian, 0);
		this.setBlock(world, i + 8, j + 5, k + 7, Blocks.obsidian, 0);
		this.setBlock(world, i + 8, j + 6, k + 3, Blocks.obsidian, 0);
		this.setBlock(world, i + 8, j + 6, k + 4, Blocks.obsidian, 0);
		this.setBlock(world, i + 8, j + 6, k + 5, Blocks.obsidian, 0);
		this.setBlock(world, i + 8, j + 6, k + 6, Blocks.obsidian, 0);
		this.setBlock(world, i + 9, j + 0, k + 0, Blocks.dirt, 0);
		this.setBlock(world, i + 9, j + 0, k + 1, Blocks.grass, 0);
		this.setBlock(world, i + 9, j + 0, k + 2, Blocks.grass, 0);
		this.setBlock(world, i + 9, j + 0, k + 3, Blocks.dirt, 0);
		this.setBlock(world, i + 9, j + 0, k + 4, Blocks.dirt, 0);
		this.setBlock(world, i + 9, j + 0, k + 5, Blocks.dirt, 0);
		this.setBlock(world, i + 9, j + 0, k + 6, Blocks.dirt, 0);
		this.setBlock(world, i + 9, j + 0, k + 7, Blocks.grass, 0);
		this.setBlock(world, i + 9, j + 0, k + 8, Blocks.grass, 0);
		this.setBlock(world, i + 9, j + 0, k + 9, Blocks.grass, 0);
		this.setBlock(world, i + 9, j + 1, k + 0, Blocks.obsidian, 0);
		this.setBlock(world, i + 9, j + 1, k + 3, Blocks.obsidian, 0);
		this.setBlock(world, i + 9, j + 1, k + 4, Blocks.obsidian, 0);
		this.setBlock(world, i + 9, j + 1, k + 5, Blocks.obsidian, 0);
		this.setBlock(world, i + 9, j + 1, k + 6, Blocks.obsidian, 0);
		this.setBlock(world, i + 9, j + 1, k + 9, Blocks.obsidian, 0);
		this.setBlock(world, i + 9, j + 2, k + 0, Blocks.obsidian, 0);
		this.setBlock(world, i + 9, j + 2, k + 3, Blocks.glowstone, 0);
		this.setBlock(world, i + 9, j + 2, k + 6, Blocks.glowstone, 0);
		this.setBlock(world, i + 9, j + 2, k + 9, Blocks.obsidian, 0);
		this.setBlock(world, i + 9, j + 3, k + 0, Blocks.glowstone, 0);
		this.setBlock(world, i + 9, j + 3, k + 3, Blocks.glowstone, 0);
		this.setBlock(world, i + 9, j + 3, k + 6, Blocks.glowstone, 0);
		this.setBlock(world, i + 9, j + 3, k + 9, Blocks.glowstone, 0);
		this.setBlock(world, i + 9, j + 4, k + 3, Blocks.glowstone, 0);
		this.setBlock(world, i + 9, j + 4, k + 6, Blocks.glowstone, 0);
		this.setBlock(world, i + 9, j + 5, k + 3, Blocks.glowstone, 0);
		this.setBlock(world, i + 9, j + 5, k + 4, Blocks.obsidian, 0);
		this.setBlock(world, i + 9, j + 5, k + 5, Blocks.obsidian, 0);
		this.setBlock(world, i + 9, j + 5, k + 6, Blocks.glowstone, 0);
		/*world.setBlockAndMetadataWithNotify(i + 9, j + 2, k + 1, 2, 2);
		world.setBlockAndMetadataWithNotify(i + 9, j + 2, k + 2, 2, 2);
		world.setBlockAndMetadataWithNotify(i + 9, j + 3, k + 1, 9, 2);
		world.setBlockAndMetadataWithNotify(i + 9, j + 3, k + 2, 8, 2);*/

		return true;
	}
	public boolean generate2(World world, Random rand, int i, int j, int k) {
		//check that each corner is one of the valid spawn blocks
		

		//k = k - 10;
		//i = i - 10;
		for (int y = j; y < j+16; y++){
			for (int x = i; x < i+16; x++){
				for (int z = k; z < k+16; z++){
					this.setBlock(world, x, y, z, Blocks.air, 0);
				}
			}
		}
		this.setBlock(world, i + 0, j + 1, k + 0, Blocks.stonebrick, 0);
		this.setBlock(world, i + 0, j + 1, k + 1, Blocks.iron_bars, 0); 
		this.setBlock(world, i + 0, j + 1, k + 2, Blocks.iron_bars, 0);
		this.setBlock(world, i + 0, j + 1, k + 3, Blocks.iron_bars, 0);
		this.setBlock(world, i + 0, j + 1, k + 4, Blocks.iron_bars, 0);
		this.setBlock(world, i + 0, j + 1, k + 5, Blocks.iron_bars, 0);
		this.setBlock(world, i + 0, j + 1, k + 6, Blocks.iron_bars, 0);
		this.setBlock(world, i + 0, j + 1, k + 7, Blocks.iron_bars, 0);
		this.setBlock(world, i + 0, j + 1, k + 8, Blocks.iron_bars, 0);
		this.setBlock(world, i + 0, j + 1, k + 9, Blocks.iron_bars, 0);
		this.setBlock(world, i + 0, j + 1, k + 10, Blocks.iron_bars, 0);
		this.setBlock(world, i + 0, j + 1, k + 11, Blocks.iron_bars, 0);
		this.setBlock(world, i + 0, j + 1, k + 12, Blocks.iron_bars, 0);
		this.setBlock(world, i + 0, j + 1, k + 13, Blocks.iron_bars, 0);
		this.setBlock(world, i + 0, j + 1, k + 14, Blocks.iron_bars, 0);
		this.setBlock(world, i + 0, j + 1, k + 15, Blocks.stonebrick, 0);
		this.setBlock(world, i + 0, j + 2, k + 0, Blocks.stonebrick, 0);
		this.setBlock(world, i + 0, j + 2, k + 1, Blocks.iron_bars, 0);
		this.setBlock(world, i + 0, j + 2, k + 2, Blocks.iron_bars, 0);
		this.setBlock(world, i + 0, j + 2, k + 3, Blocks.iron_bars, 0);
		this.setBlock(world, i + 0, j + 2, k + 4, Blocks.iron_bars, 0);
		this.setBlock(world, i + 0, j + 2, k + 5, Blocks.iron_bars, 0);
		this.setBlock(world, i + 0, j + 2, k + 6, Blocks.iron_bars, 0);
		this.setBlock(world, i + 0, j + 2, k + 7, Blocks.iron_bars, 0);
		this.setBlock(world, i + 0, j + 2, k + 8, Blocks.iron_bars, 0);
		this.setBlock(world, i + 0, j + 2, k + 9, Blocks.iron_bars, 0);
		this.setBlock(world, i + 0, j + 2, k + 10, Blocks.iron_bars, 0);
		this.setBlock(world, i + 0, j + 2, k + 11, Blocks.iron_bars, 0);
		this.setBlock(world, i + 0, j + 2, k + 12, Blocks.iron_bars, 0);
		this.setBlock(world, i + 0, j + 2, k + 13, Blocks.iron_bars, 0);
		this.setBlock(world, i + 0, j + 2, k + 14, Blocks.iron_bars, 0);
		this.setBlock(world, i + 0, j + 2, k + 15, Blocks.stonebrick, 0);
		this.setBlock(world, i + 0, j + 3, k + 0, Blocks.stonebrick, 0);
		this.setBlock(world, i + 0, j + 3, k + 1, Blocks.iron_bars, 0);
		this.setBlock(world, i + 0, j + 3, k + 2, Blocks.iron_bars, 0);
		this.setBlock(world, i + 0, j + 3, k + 3, Blocks.iron_bars, 0);
		this.setBlock(world, i + 0, j + 3, k + 4, Blocks.iron_bars, 0);
		this.setBlock(world, i + 0, j + 3, k + 5, Blocks.iron_bars, 0);
		this.setBlock(world, i + 0, j + 3, k + 6, Blocks.iron_bars, 0);
		this.setBlock(world, i + 0, j + 3, k + 7, Blocks.iron_bars, 0);
		this.setBlock(world, i + 0, j + 3, k + 8, Blocks.iron_bars, 0);
		this.setBlock(world, i + 0, j + 3, k + 9, Blocks.iron_bars, 0);
		this.setBlock(world, i + 0, j + 3, k + 10, Blocks.iron_bars, 0);
		this.setBlock(world, i + 0, j + 3, k + 11, Blocks.iron_bars, 0);
		this.setBlock(world, i + 0, j + 3, k + 12, Blocks.iron_bars, 0);
		this.setBlock(world, i + 0, j + 3, k + 13, Blocks.iron_bars, 0);
		this.setBlock(world, i + 0, j + 3, k + 14, Blocks.iron_bars, 0);
		this.setBlock(world, i + 0, j + 3, k + 15, Blocks.stonebrick, 0);
		this.setBlock(world, i + 0, j + 4, k + 0, Blocks.stonebrick, 0);
		this.setBlock(world, i + 0, j + 4, k + 1, Blocks.stonebrick, 0);
		this.setBlock(world, i + 0, j + 4, k + 2, Blocks.stonebrick, 0);
		this.setBlock(world, i + 0, j + 4, k + 3, Blocks.stonebrick, 0);
		this.setBlock(world, i + 0, j + 4, k + 4, Blocks.stonebrick, 0);
		this.setBlock(world, i + 0, j + 4, k + 5, Blocks.stonebrick, 0);
		this.setBlock(world, i + 0, j + 4, k + 6, Blocks.stonebrick, 0);
		this.setBlock(world, i + 0, j + 4, k + 7, Blocks.stonebrick, 0);
		this.setBlock(world, i + 0, j + 4, k + 8, Blocks.stonebrick, 0);
		this.setBlock(world, i + 0, j + 4, k + 9, Blocks.stonebrick, 0);
		this.setBlock(world, i + 0, j + 4, k + 10, Blocks.stonebrick, 0);
		this.setBlock(world, i + 0, j + 4, k + 11, Blocks.stonebrick, 0);
		this.setBlock(world, i + 0, j + 4, k + 12, Blocks.stonebrick, 0);
		this.setBlock(world, i + 0, j + 4, k + 13, Blocks.stonebrick, 0);
		this.setBlock(world, i + 0, j + 4, k + 14, Blocks.stonebrick, 0);
		this.setBlock(world, i + 0, j + 4, k + 15, Blocks.stonebrick, 0);
		this.setBlock(world, i + 0, j + 5, k + 0, Blocks.stonebrick, 0);
		this.setBlock(world, i + 0, j + 5, k + 15, Blocks.stonebrick, 0);
		this.setBlock(world, i + 0, j + 6, k + 0, Blocks.stonebrick, 0);
		this.setBlock(world, i + 0, j + 6, k + 15, Blocks.stonebrick, 0);
		this.setBlock(world, i + 0, j + 7, k + 0, Blocks.stonebrick, 0);
		this.setBlock(world, i + 0, j + 7, k + 15, Blocks.stonebrick, 0);
		this.setBlock(world, i + 0, j + 8, k + 0, Blocks.stonebrick, 0);
		this.setBlock(world, i + 0, j + 8, k + 15, Blocks.stonebrick, 0);
		this.setBlock(world, i + 0, j + 9, k + 0, Blocks.stonebrick, 0);
		this.setBlock(world, i + 0, j + 9, k + 15, Blocks.stonebrick, 0);
		this.setBlock(world, i + 0, j + 10, k + 0, Blocks.stonebrick, 0);
		this.setBlock(world, i + 0, j + 10, k + 15, Blocks.stonebrick, 0);
		this.setBlock(world, i + 0, j + 11, k + 0, Blocks.stonebrick, 0);
		this.setBlock(world, i + 0, j + 11, k + 1, Blocks.stonebrick, 0);
		this.setBlock(world, i + 0, j + 11, k + 14, Blocks.stonebrick, 0);
		this.setBlock(world, i + 0, j + 11, k + 15, Blocks.stonebrick, 0);
		this.setBlock(world, i + 1, j + 1, k + 0, Blocks.iron_bars, 0);
		this.setBlock(world, i + 1, j + 1, k + 15, Blocks.iron_bars, 0);
		this.setBlock(world, i + 1, j + 2, k + 0, Blocks.iron_bars, 0);
		this.setBlock(world, i + 1, j + 2, k + 15, Blocks.iron_bars, 0);
		this.setBlock(world, i + 1, j + 3, k + 0, Blocks.iron_bars, 0);
		this.setBlock(world, i + 1, j + 3, k + 15, Blocks.iron_bars, 0);
		this.setBlock(world, i + 1, j + 4, k + 0, Blocks.stonebrick, 0);
		this.setBlock(world, i + 1, j + 4, k + 15, Blocks.stonebrick, 0);
		this.setBlock(world, i + 1, j + 11, k + 0, Blocks.glowstone, 0);
		this.setBlock(world, i + 1, j + 11, k + 1, Blocks.stonebrick, 0);
		this.setBlock(world, i + 1, j + 11, k + 14, Blocks.glowstone, 0);
		this.setBlock(world, i + 1, j + 11, k + 15, Blocks.stonebrick, 0);
		this.setBlock(world, i + 2, j + 1, k + 0, Blocks.iron_bars, 0);
		this.setBlock(world, i + 2, j + 1, k + 15, Blocks.iron_bars, 0);
		this.setBlock(world, i + 2, j + 2, k + 0, Blocks.iron_bars, 0);
		this.setBlock(world, i + 2, j + 2, k + 15, Blocks.iron_bars, 0);
		this.setBlock(world, i + 2, j + 3, k + 0, Blocks.iron_bars, 0);
		this.setBlock(world, i + 2, j + 3, k + 15, Blocks.iron_bars, 0);
		this.setBlock(world, i + 2, j + 4, k + 0, Blocks.stonebrick, 0);
		this.setBlock(world, i + 2, j + 4, k + 15, Blocks.stonebrick, 0);
		this.setBlock(world, i + 3, j + 1, k + 0, Blocks.iron_bars, 0);
		this.setBlock(world, i + 3, j + 1, k + 3, Blocks.stonebrick, 0);
		this.setBlock(world, i + 3, j + 1, k + 4, Blocks.stonebrick, 0);
		this.setBlock(world, i + 3, j + 1, k + 5, Blocks.stonebrick, 0);
		this.setBlock(world, i + 3, j + 1, k + 6, Blocks.stonebrick, 0);
		this.setBlock(world, i + 3, j + 1, k + 7, Blocks.stonebrick, 0);
		this.setBlock(world, i + 3, j + 1, k + 8, Blocks.stonebrick, 0);
		this.setBlock(world, i + 3, j + 1, k + 9, Blocks.stonebrick, 0);
		this.setBlock(world, i + 3, j + 1, k + 10, Blocks.stonebrick, 0);
		this.setBlock(world, i + 3, j + 1, k + 11, Blocks.stonebrick, 0);
		this.setBlock(world, i + 3, j + 1, k + 12, Blocks.stonebrick, 0);
		this.setBlock(world, i + 3, j + 1, k + 15, Blocks.iron_bars, 0);
		this.setBlock(world, i + 3, j + 2, k + 0, Blocks.iron_bars, 0);
		this.setBlock(world, i + 3, j + 2, k + 3, Blocks.stonebrick, 0);
		this.setBlock(world, i + 3, j + 2, k + 4, Blocks.stonebrick, 0);
		this.setBlock(world, i + 3, j + 2, k + 5, Blocks.iron_bars, 0);
		this.setBlock(world, i + 3, j + 2, k + 6, Blocks.stonebrick, 0);
		this.setBlock(world, i + 3, j + 2, k + 7, Blocks.stonebrick, 0);
		this.setBlock(world, i + 3, j + 2, k + 8, Blocks.stonebrick, 0);
		this.setBlock(world, i + 3, j + 2, k + 9, Blocks.stonebrick, 0);
		this.setBlock(world, i + 3, j + 2, k + 10, Blocks.iron_bars, 0);
		this.setBlock(world, i + 3, j + 2, k + 11, Blocks.stonebrick, 0);
		this.setBlock(world, i + 3, j + 2, k + 12, Blocks.stonebrick, 0);
		this.setBlock(world, i + 3, j + 2, k + 15, Blocks.iron_bars, 0);
		this.setBlock(world, i + 3, j + 3, k + 0, Blocks.iron_bars, 0);
		this.setBlock(world, i + 3, j + 3, k + 3, Blocks.stonebrick, 0);
		this.setBlock(world, i + 3, j + 3, k + 4, Blocks.stonebrick, 0);
		this.setBlock(world, i + 3, j + 3, k + 5, Blocks.stonebrick, 0);
		this.setBlock(world, i + 3, j + 3, k + 6, Blocks.stonebrick, 0);
		this.setBlock(world, i + 3, j + 3, k + 7, Blocks.stonebrick, 0);
		this.setBlock(world, i + 3, j + 3, k + 8, Blocks.stonebrick, 0);
		this.setBlock(world, i + 3, j + 3, k + 9, Blocks.stonebrick, 0);
		this.setBlock(world, i + 3, j + 3, k + 10, Blocks.stonebrick, 0);
		this.setBlock(world, i + 3, j + 3, k + 11, Blocks.stonebrick, 0);
		this.setBlock(world, i + 3, j + 3, k + 12, Blocks.stonebrick, 0);
		this.setBlock(world, i + 3, j + 3, k + 15, Blocks.iron_bars, 0);
		this.setBlock(world, i + 3, j + 4, k + 0, Blocks.stonebrick, 0);
		this.setBlock(world, i + 3, j + 4, k + 3, Blocks.stonebrick, 0);
		this.setBlock(world, i + 3, j + 4, k + 4, Blocks.stonebrick, 0);
		this.setBlock(world, i + 3, j + 4, k + 5, Blocks.stonebrick, 0);
		this.setBlock(world, i + 3, j + 4, k + 6, Blocks.stonebrick, 0);
		this.setBlock(world, i + 3, j + 4, k + 7, Blocks.stonebrick, 0);
		this.setBlock(world, i + 3, j + 4, k + 8, Blocks.stonebrick, 0);
		this.setBlock(world, i + 3, j + 4, k + 9, Blocks.stonebrick, 0);
		this.setBlock(world, i + 3, j + 4, k + 10, Blocks.stonebrick, 0);
		this.setBlock(world, i + 3, j + 4, k + 11, Blocks.stonebrick, 0);
		this.setBlock(world, i + 3, j + 4, k + 12, Blocks.stonebrick, 0);
		this.setBlock(world, i + 3, j + 4, k + 15, Blocks.stonebrick, 0);
		this.setBlock(world, i + 3, j + 5, k + 3, Blocks.stonebrick, 0);
		this.setBlock(world, i + 3, j + 5, k + 4, Blocks.stonebrick, 0);
		this.setBlock(world, i + 3, j + 5, k + 5, Blocks.stonebrick, 0);
		this.setBlock(world, i + 3, j + 5, k + 6, Blocks.stonebrick, 0);
		this.setBlock(world, i + 3, j + 5, k + 7, Blocks.stonebrick, 0);
		this.setBlock(world, i + 3, j + 5, k + 8, Blocks.stonebrick, 0);
		this.setBlock(world, i + 3, j + 5, k + 9, Blocks.stonebrick, 0);
		this.setBlock(world, i + 3, j + 5, k + 10, Blocks.stonebrick, 0);
		this.setBlock(world, i + 3, j + 5, k + 11, Blocks.stonebrick, 0);
		this.setBlock(world, i + 3, j + 5, k + 12, Blocks.stonebrick, 0);
		this.setBlock(world, i + 3, j + 6, k + 3, Blocks.stonebrick, 0);
		this.setBlock(world, i + 3, j + 6, k + 4, Blocks.stonebrick, 0);
		this.setBlock(world, i + 3, j + 6, k + 5, Blocks.stonebrick, 0);
		this.setBlock(world, i + 3, j + 6, k + 6, Blocks.stonebrick, 0);
		this.setBlock(world, i + 3, j + 6, k + 7, Blocks.stonebrick, 0);
		this.setBlock(world, i + 3, j + 6, k + 8, Blocks.stonebrick, 0);
		this.setBlock(world, i + 3, j + 6, k + 9, Blocks.stonebrick, 0);
		this.setBlock(world, i + 3, j + 6, k + 10, Blocks.stonebrick, 0);
		this.setBlock(world, i + 3, j + 6, k + 11, Blocks.stonebrick, 0);
		this.setBlock(world, i + 3, j + 6, k + 12, Blocks.stonebrick, 0);
		this.setBlock(world, i + 3, j + 7, k + 3, Blocks.stonebrick, 0);
		this.setBlock(world, i + 3, j + 7, k + 4, Blocks.stonebrick, 0);
		this.setBlock(world, i + 3, j + 7, k + 5, Blocks.stonebrick, 0);
		this.setBlock(world, i + 3, j + 7, k + 6, Blocks.stonebrick, 0);
		this.setBlock(world, i + 3, j + 7, k + 7, Blocks.stonebrick, 0);
		this.setBlock(world, i + 3, j + 7, k + 8, Blocks.stonebrick, 0);
		this.setBlock(world, i + 3, j + 7, k + 9, Blocks.stonebrick, 0);
		this.setBlock(world, i + 3, j + 7, k + 10, Blocks.stonebrick, 0);
		this.setBlock(world, i + 3, j + 7, k + 11, Blocks.stonebrick, 0);
		this.setBlock(world, i + 3, j + 7, k + 12, Blocks.stonebrick, 0);
		this.setBlock(world, i + 3, j + 8, k + 3, Blocks.stonebrick, 0);
		this.setBlock(world, i + 3, j + 8, k + 4, Blocks.stonebrick, 0);
		this.setBlock(world, i + 3, j + 8, k + 5, Blocks.stonebrick, 0);
		this.setBlock(world, i + 3, j + 8, k + 6, Blocks.stonebrick, 0);
		this.setBlock(world, i + 3, j + 8, k + 7, Blocks.stonebrick, 0);
		this.setBlock(world, i + 3, j + 8, k + 8, Blocks.stonebrick, 0);
		this.setBlock(world, i + 3, j + 8, k + 9, Blocks.stonebrick, 0);
		this.setBlock(world, i + 3, j + 8, k + 10, Blocks.stonebrick, 0);
		this.setBlock(world, i + 3, j + 8, k + 11, Blocks.stonebrick, 0);
		this.setBlock(world, i + 3, j + 8, k + 12, Blocks.stonebrick, 0);
		this.setBlock(world, i + 4, j + 1, k + 0, Blocks.iron_bars, 0);
		this.setBlock(world, i + 4, j + 1, k + 3, Blocks.stonebrick, 0);
		this.setBlock(world, i + 4, j + 1, k + 4, Blocks.redstone_block, 0);
		this.setBlock(world, i + 4, j + 1, k + 11, Blocks.redstone_block, 0);
		this.setBlock(world, i + 4, j + 1, k + 12, Blocks.stonebrick, 0);
		this.setBlock(world, i + 4, j + 1, k + 15, Blocks.iron_bars, 0);
		this.setBlock(world, i + 4, j + 2, k + 0, Blocks.iron_bars, 0);
		this.setBlock(world, i + 4, j + 2, k + 3, Blocks.stonebrick, 0);
		this.setBlock(world, i + 4, j + 1, k + 4, Blocks.redstone_block, 0);
		this.setBlock(world, i + 4, j + 1, k + 11, Blocks.redstone_block, 0);
		this.setBlock(world, i + 4, j + 2, k + 4, Blocks.redstone_lamp, 0);
		this.setBlock(world, i + 4, j + 2, k + 11, Blocks.redstone_lamp, 0);
		this.setBlock(world, i + 4, j + 2, k + 12, Blocks.stonebrick, 0);
		this.setBlock(world, i + 4, j + 2, k + 15, Blocks.iron_bars, 0);
		this.setBlock(world, i + 4, j + 3, k + 0, Blocks.iron_bars, 0);
		this.setBlock(world, i + 4, j + 3, k + 3, Blocks.stonebrick, 0);
		this.setBlock(world, i + 4, j + 3, k + 12, Blocks.stonebrick, 0);
		this.setBlock(world, i + 4, j + 3, k + 15, Blocks.iron_bars, 0);
		this.setBlock(world, i + 4, j + 4, k + 0, Blocks.stonebrick, 0);
		this.setBlock(world, i + 4, j + 4, k + 3, Blocks.stonebrick, 0);
		this.setBlock(world, i + 4, j + 4, k + 4, Blocks.stonebrick, 0);
		this.setBlock(world, i + 4, j + 4, k + 5, Blocks.stonebrick, 0);
		this.setBlock(world, i + 4, j + 4, k + 6, Blocks.stonebrick, 0);
		this.setBlock(world, i + 4, j + 4, k + 7, Blocks.stonebrick, 0);
		this.setBlock(world, i + 4, j + 4, k + 8, Blocks.stonebrick, 0);
		this.setBlock(world, i + 4, j + 4, k + 9, Blocks.stonebrick, 0);
		this.setBlock(world, i + 4, j + 4, k + 10, Blocks.stonebrick, 0);
		this.setBlock(world, i + 4, j + 4, k + 11, Blocks.stonebrick, 0);
		this.setBlock(world, i + 4, j + 4, k + 12, Blocks.stonebrick, 0);
		this.setBlock(world, i + 4, j + 4, k + 15, Blocks.stonebrick, 0);
		this.setBlock(world, i + 4, j + 5, k + 3, Blocks.stonebrick, 0);
		this.setBlock(world, i + 4, j + 5, k + 4, Blocks.redstone_block, 0);
		this.setBlock(world, i + 4, j + 5, k + 11, Blocks.redstone_block, 0);
		this.setBlock(world, i + 4, j + 5, k + 12, Blocks.stonebrick, 0);
		this.setBlock(world, i + 4, j + 6, k + 3, Blocks.stonebrick, 0);
		this.setBlock(world, i + 4, j + 6, k + 4, Blocks.redstone_lamp, 0);
		this.setBlock(world, i + 4, j + 6, k + 11, Blocks.redstone_lamp, 0);
		this.setBlock(world, i + 4, j + 6, k + 12, Blocks.stonebrick, 0);
		this.setBlock(world, i + 4, j + 7, k + 3, Blocks.stonebrick, 0);
		this.setBlock(world, i + 4, j + 7, k + 12, Blocks.stonebrick, 0);
		this.setBlock(world, i + 4, j + 8, k + 3, Blocks.stonebrick, 0);
		this.setBlock(world, i + 4, j + 8, k + 4, Blocks.stonebrick, 0);
		this.setBlock(world, i + 4, j + 8, k + 5, Blocks.stonebrick, 0);
		this.setBlock(world, i + 4, j + 8, k + 6, Blocks.stonebrick, 0);
		this.setBlock(world, i + 4, j + 8, k + 7, Blocks.stonebrick, 0);
		this.setBlock(world, i + 4, j + 8, k + 8, Blocks.stonebrick, 0);
		this.setBlock(world, i + 4, j + 8, k + 9, Blocks.stonebrick, 0);
		this.setBlock(world, i + 4, j + 8, k + 10, Blocks.stonebrick, 0);
		this.setBlock(world, i + 4, j + 8, k + 11, Blocks.stonebrick, 0);
		this.setBlock(world, i + 4, j + 8, k + 12, Blocks.stonebrick, 0);
		this.setBlock(world, i + 5, j + 1, k + 0, Blocks.iron_bars, 0);
		this.setBlock(world, i + 5, j + 1, k + 3, Blocks.stonebrick, 0);
		this.setBlock(world, i + 5, j + 1, k + 12, Blocks.stonebrick, 0);
		this.setBlock(world, i + 5, j + 1, k + 15, Blocks.iron_bars, 0);
		this.setBlock(world, i + 5, j + 2, k + 0, Blocks.iron_bars, 0);
		this.setBlock(world, i + 5, j + 2, k + 3, Blocks.iron_bars, 0);
		this.setBlock(world, i + 5, j + 2, k + 12, Blocks.iron_bars, 0);
		this.setBlock(world, i + 5, j + 2, k + 15, Blocks.iron_bars, 0);
		this.setBlock(world, i + 5, j + 3, k + 0, Blocks.iron_bars, 0);
		this.setBlock(world, i + 5, j + 3, k + 3, Blocks.stonebrick, 0);
		this.setBlock(world, i + 5, j + 3, k + 12, Blocks.stonebrick, 0);
		this.setBlock(world, i + 5, j + 3, k + 15, Blocks.iron_bars, 0);
		this.setBlock(world, i + 5, j + 4, k + 0, Blocks.stonebrick, 0);
		this.setBlock(world, i + 5, j + 4, k + 3, Blocks.stonebrick, 0);
		this.setBlock(world, i + 5, j + 4, k + 4, Blocks.stonebrick, 0);
		this.setBlock(world, i + 5, j + 4, k + 5, Blocks.stonebrick, 0);
		this.setBlock(world, i + 5, j + 4, k + 6, Blocks.stonebrick, 0);
		this.setBlock(world, i + 5, j + 4, k + 7, Blocks.stonebrick, 0);
		this.setBlock(world, i + 5, j + 4, k + 8, Blocks.stonebrick, 0);
		this.setBlock(world, i + 5, j + 4, k + 9, Blocks.stonebrick, 0);
		this.setBlock(world, i + 5, j + 4, k + 10, Blocks.stonebrick, 0);
		this.setBlock(world, i + 5, j + 4, k + 11, Blocks.stonebrick, 0);
		this.setBlock(world, i + 5, j + 4, k + 12, Blocks.stonebrick, 0);
		this.setBlock(world, i + 5, j + 4, k + 15, Blocks.stonebrick, 0);
		this.setBlock(world, i + 5, j + 5, k + 3, Blocks.stonebrick, 0);
		this.setBlock(world, i + 5, j + 5, k + 12, Blocks.stonebrick, 0);
		this.setBlock(world, i + 5, j + 6, k + 3, Blocks.stonebrick, 0);
		this.setBlock(world, i + 5, j + 6, k + 12, Blocks.stonebrick, 0);
		this.setBlock(world, i + 5, j + 7, k + 3, Blocks.stonebrick, 0);
		this.setBlock(world, i + 5, j + 7, k + 12, Blocks.stonebrick, 0);
		this.setBlock(world, i + 5, j + 8, k + 3, Blocks.stonebrick, 0);
		this.setBlock(world, i + 5, j + 8, k + 4, Blocks.stonebrick, 0);
		this.setBlock(world, i + 5, j + 8, k + 5, Blocks.stonebrick, 0);
		this.setBlock(world, i + 5, j + 8, k + 6, Blocks.stonebrick, 0);
		this.setBlock(world, i + 5, j + 8, k + 7, Blocks.stonebrick, 0);
		this.setBlock(world, i + 5, j + 8, k + 8, Blocks.stonebrick, 0);
		this.setBlock(world, i + 5, j + 8, k + 9, Blocks.stonebrick, 0);
		this.setBlock(world, i + 5, j + 8, k + 10, Blocks.stonebrick, 0);
		this.setBlock(world, i + 5, j + 8, k + 11, Blocks.stonebrick, 0);
		this.setBlock(world, i + 5, j + 8, k + 12, Blocks.stonebrick, 0);
		this.setBlock(world, i + 6, j + 1, k + 0, Blocks.iron_bars, 0);
		this.setBlock(world, i + 6, j + 1, k + 3, Blocks.stonebrick, 0);
		this.setBlock(world, i + 6, j + 1, k + 11, Blocks.chest, 2);
		TileEntityChest gunchest = (TileEntityChest)world.getTileEntity(new BlockPos(i + 6, j + 1, k + 11));
		gunchest.setInventorySlotContents(0, new ItemStack(ZombieApocalypse.m9, 1));
		gunchest.setInventorySlotContents(1, new ItemStack(ZombieApocalypse.m9, 1));
		gunchest.setInventorySlotContents(2, new ItemStack(ZombieApocalypse.m9, 1));
		gunchest.setInventorySlotContents(3, new ItemStack(ZombieApocalypse.m11_clip, 2));
		gunchest.setInventorySlotContents(4, new ItemStack(ZombieApocalypse.m11_clip, 2));
		gunchest.setInventorySlotContents(5, new ItemStack(ZombieApocalypse.m11_clip, 2));
		
		gunchest.setInventorySlotContents(6, new ItemStack(ZombieApocalypse.m4, 1));
		gunchest.setInventorySlotContents(7, new ItemStack(ZombieApocalypse.m4, 1));
		gunchest.setInventorySlotContents(8, new ItemStack(ZombieApocalypse.m4, 1));
		gunchest.setInventorySlotContents(9, new ItemStack(ZombieApocalypse.m16_clip, 2));
		gunchest.setInventorySlotContents(10, new ItemStack(ZombieApocalypse.m16_clip, 2));
		gunchest.setInventorySlotContents(11, new ItemStack(ZombieApocalypse.m16_clip, 2));
		this.setBlock(world, i + 6, j + 1, k + 12, Blocks.stonebrick, 0);
		this.setBlock(world, i + 6, j + 1, k + 15, Blocks.stonebrick, 0);
		this.setBlock(world, i + 6, j + 2, k + 0, Blocks.iron_bars, 0);
		this.setBlock(world, i + 6, j + 2, k + 3, Blocks.stonebrick, 0);
		this.setBlock(world, i + 6, j + 2, k + 12, Blocks.stonebrick, 0);
		this.setBlock(world, i + 6, j + 2, k + 15, Blocks.stonebrick, 0);
		this.setBlock(world, i + 6, j + 3, k + 0, Blocks.iron_bars, 0);
		this.setBlock(world, i + 6, j + 3, k + 3, Blocks.stonebrick, 0);
		this.setBlock(world, i + 6, j + 3, k + 12, Blocks.stonebrick, 0);
		this.setBlock(world, i + 6, j + 3, k + 15, Blocks.iron_bars, 0);
		this.setBlock(world, i + 6, j + 4, k + 0, Blocks.stonebrick, 0);
		this.setBlock(world, i + 6, j + 4, k + 3, Blocks.stonebrick, 0);
		this.setBlock(world, i + 6, j + 4, k + 4, Blocks.stonebrick, 0);
		this.setBlock(world, i + 6, j + 4, k + 5, Blocks.stonebrick, 0);
		this.setBlock(world, i + 6, j + 4, k + 6, Blocks.stonebrick, 0);
		this.setBlock(world, i + 6, j + 4, k + 7, Blocks.stonebrick, 0);
		this.setBlock(world, i + 6, j + 4, k + 8, Blocks.stonebrick, 0);
		this.setBlock(world, i + 6, j + 4, k + 9, Blocks.stonebrick, 0);
		this.setBlock(world, i + 6, j + 4, k + 10, Blocks.stonebrick, 0);
		this.setBlock(world, i + 6, j + 4, k + 11, Blocks.stonebrick, 0);
		this.setBlock(world, i + 6, j + 4, k + 12, Blocks.stonebrick, 0);
		this.setBlock(world, i + 6, j + 4, k + 15, Blocks.stonebrick, 0);
		this.setBlock(world, i + 6, j + 5, k + 3, Blocks.stonebrick, 0);
		this.setBlock(world, i + 6, j + 5, k + 12, Blocks.stonebrick, 0);
		this.setBlock(world, i + 6, j + 6, k + 3, Blocks.stonebrick, 0);
		this.setBlock(world, i + 6, j + 6, k + 12, Blocks.stonebrick, 0);
		this.setBlock(world, i + 6, j + 7, k + 3, Blocks.stonebrick, 0);
		this.setBlock(world, i + 6, j + 7, k + 12, Blocks.stonebrick, 0);
		this.setBlock(world, i + 6, j + 8, k + 3, Blocks.stonebrick, 0);
		this.setBlock(world, i + 6, j + 8, k + 4, Blocks.stonebrick, 0);
		this.setBlock(world, i + 6, j + 8, k + 5, Blocks.stonebrick, 0);
		this.setBlock(world, i + 6, j + 8, k + 6, Blocks.stonebrick, 0);
		this.setBlock(world, i + 6, j + 8, k + 7, Blocks.stonebrick, 0);
		this.setBlock(world, i + 6, j + 8, k + 8, Blocks.stonebrick, 0);
		this.setBlock(world, i + 6, j + 8, k + 9, Blocks.stonebrick, 0);
		this.setBlock(world, i + 6, j + 8, k + 10, Blocks.stonebrick, 0);
		this.setBlock(world, i + 6, j + 8, k + 11, Blocks.stonebrick, 0);
		this.setBlock(world, i + 6, j + 8, k + 12, Blocks.stonebrick, 0);
		this.setBlock(world, i + 7, j + 1, k + 0, Blocks.iron_bars, 0);
		this.setBlock(world, i + 7, j + 1, k + 3, Blocks.stonebrick, 0);
		this.setBlock(world, i + 7, j + 1, k + 8, Blocks.stonebrick, 0);
		this.setBlock(world, i + 7, j + 1, k + 9, Blocks.stonebrick, 0);
		this.setBlock(world, i + 7, j + 2, k + 0, Blocks.iron_bars, 0);
		this.setBlock(world, i + 7, j + 2, k + 3, Blocks.stonebrick, 0);
		this.setBlock(world, i + 7, j + 3, k + 0, Blocks.iron_bars, 0);
		this.setBlock(world, i + 7, j + 3, k + 3, Blocks.stonebrick, 0);
		this.setBlock(world, i + 7, j + 3, k + 12, Blocks.stonebrick, 0);
		this.setBlock(world, i + 7, j + 3, k + 15, Blocks.iron_bars, 0);
		this.setBlock(world, i + 7, j + 4, k + 0, Blocks.stonebrick, 0);
		this.setBlock(world, i + 7, j + 4, k + 3, Blocks.stonebrick, 0);
		this.setBlock(world, i + 7, j + 4, k + 4, Blocks.stonebrick, 0);
		this.setBlock(world, i + 7, j + 4, k + 5, Blocks.stonebrick, 0);
		this.setBlock(world, i + 7, j + 4, k + 6, Blocks.stonebrick, 0);
		this.setBlock(world, i + 7, j + 4, k + 7, Blocks.stonebrick, 0);
		this.setBlock(world, i + 7, j + 4, k + 8, Blocks.stonebrick, 0);
		this.setBlock(world, i + 7, j + 4, k + 9, Blocks.stonebrick, 0);
		this.setBlock(world, i + 7, j + 4, k + 10, Blocks.stonebrick, 0);
		this.setBlock(world, i + 7, j + 4, k + 11, Blocks.stonebrick, 0);
		this.setBlock(world, i + 7, j + 4, k + 12, Blocks.stonebrick, 0);
		this.setBlock(world, i + 7, j + 4, k + 15, Blocks.stonebrick, 0);
		this.setBlock(world, i + 7, j + 5, k + 3, Blocks.stonebrick, 0);
		this.setBlock(world, i + 7, j + 5, k + 12, Blocks.stonebrick, 0);
		this.setBlock(world, i + 7, j + 6, k + 3, Blocks.stonebrick, 0);
		this.setBlock(world, i + 7, j + 6, k + 12, Blocks.stonebrick, 0);
		this.setBlock(world, i + 7, j + 7, k + 3, Blocks.stonebrick, 0);
		this.setBlock(world, i + 7, j + 7, k + 12, Blocks.stonebrick, 0);
		this.setBlock(world, i + 7, j + 8, k + 3, Blocks.stonebrick, 0);
		this.setBlock(world, i + 7, j + 8, k + 4, Blocks.stonebrick, 0);
		this.setBlock(world, i + 7, j + 8, k + 5, Blocks.stonebrick, 0);
		this.setBlock(world, i + 7, j + 8, k + 6, Blocks.stonebrick, 0);
		this.setBlock(world, i + 7, j + 8, k + 7, Blocks.stonebrick, 0);
		this.setBlock(world, i + 7, j + 8, k + 8, Blocks.stonebrick, 0);
		this.setBlock(world, i + 7, j + 8, k + 9, Blocks.stonebrick, 0);
		this.setBlock(world, i + 7, j + 8, k + 10, Blocks.stonebrick, 0);
		this.setBlock(world, i + 7, j + 8, k + 11, Blocks.stonebrick, 0);
		this.setBlock(world, i + 7, j + 8, k + 12, Blocks.stonebrick, 0);
		this.setBlock(world, i + 8, j + 1, k + 0, Blocks.iron_bars, 0);
		this.setBlock(world, i + 8, j + 1, k + 3, Blocks.stonebrick, 0);
		this.setBlock(world, i + 8, j + 1, k + 8, Blocks.stonebrick, 0);
		this.setBlock(world, i + 8, j + 1, k + 9, Blocks.stonebrick, 0);
		this.setBlock(world, i + 8, j + 2, k + 0, Blocks.iron_bars, 0);
		this.setBlock(world, i + 8, j + 2, k + 3, Blocks.stonebrick, 0);
		this.setBlock(world, i + 8, j + 3, k + 0, Blocks.iron_bars, 0);
		this.setBlock(world, i + 8, j + 3, k + 3, Blocks.stonebrick, 0);
		this.setBlock(world, i + 8, j + 3, k + 12, Blocks.stonebrick, 0);
		this.setBlock(world, i + 8, j + 3, k + 15, Blocks.iron_bars, 0);
		this.setBlock(world, i + 8, j + 4, k + 0, Blocks.stonebrick, 0);
		this.setBlock(world, i + 8, j + 4, k + 3, Blocks.stonebrick, 0);
		this.setBlock(world, i + 8, j + 4, k + 4, Blocks.stonebrick, 0);
		this.setBlock(world, i + 8, j + 4, k + 5, Blocks.stonebrick, 0);
		this.setBlock(world, i + 8, j + 4, k + 6, Blocks.stonebrick, 0);
		this.setBlock(world, i + 8, j + 4, k + 7, Blocks.stonebrick, 0);
		this.setBlock(world, i + 8, j + 4, k + 8, Blocks.stonebrick, 0);
		this.setBlock(world, i + 8, j + 4, k + 9, Blocks.stonebrick, 0);
		this.setBlock(world, i + 8, j + 4, k + 10, Blocks.stonebrick, 0);
		this.setBlock(world, i + 8, j + 4, k + 11, Blocks.stonebrick, 0);
		this.setBlock(world, i + 8, j + 4, k + 12, Blocks.stonebrick, 0);
		this.setBlock(world, i + 8, j + 4, k + 15, Blocks.stonebrick, 0);
		this.setBlock(world, i + 8, j + 5, k + 3, Blocks.stonebrick, 0);
		this.setBlock(world, i + 8, j + 5, k + 12, Blocks.stonebrick, 0);
		this.setBlock(world, i + 8, j + 6, k + 3, Blocks.stonebrick, 0);
		this.setBlock(world, i + 8, j + 6, k + 12, Blocks.stonebrick, 0);
		this.setBlock(world, i + 8, j + 7, k + 3, Blocks.stonebrick, 0);
		this.setBlock(world, i + 8, j + 7, k + 12, Blocks.stonebrick, 0);
		this.setBlock(world, i + 8, j + 8, k + 3, Blocks.stonebrick, 0);
		this.setBlock(world, i + 8, j + 8, k + 4, Blocks.stonebrick, 0);
		this.setBlock(world, i + 8, j + 8, k + 5, Blocks.stonebrick, 0);
		this.setBlock(world, i + 8, j + 8, k + 6, Blocks.stonebrick, 0);
		this.setBlock(world, i + 8, j + 8, k + 7, Blocks.stonebrick, 0);
		this.setBlock(world, i + 8, j + 8, k + 8, Blocks.stonebrick, 0);
		this.setBlock(world, i + 8, j + 8, k + 9, Blocks.stonebrick, 0);
		this.setBlock(world, i + 8, j + 8, k + 10, Blocks.stonebrick, 0);
		this.setBlock(world, i + 8, j + 8, k + 11, Blocks.stonebrick, 0);
		this.setBlock(world, i + 8, j + 8, k + 12, Blocks.stonebrick, 0);
		this.setBlock(world, i + 9, j + 1, k + 0, Blocks.iron_bars, 0);
		this.setBlock(world, i + 9, j + 1, k + 3, Blocks.stonebrick, 0);
		this.setBlock(world, i + 9, j + 1, k + 11, Blocks.chest, 2);
		TileEntityChest chest = (TileEntityChest)world.getTileEntity(new BlockPos(i + 9, j + 1, k + 11));
		for (int num = 0; num < 16; num++){
			chest.setInventorySlotContents(num, new ItemStack(ZombieApocalypse.bullet, 16));
		}
		
		this.setBlock(world, i + 9, j + 1, k + 12, Blocks.stonebrick, 0);
		this.setBlock(world, i + 9, j + 1, k + 15, Blocks.stonebrick, 0);
		this.setBlock(world, i + 9, j + 2, k + 0, Blocks.iron_bars, 0);
		this.setBlock(world, i + 9, j + 2, k + 3, Blocks.stonebrick, 0);
		this.setBlock(world, i + 9, j + 2, k + 12, Blocks.stonebrick, 0);
		this.setBlock(world, i + 9, j + 2, k + 15, Blocks.stonebrick, 0);
		this.setBlock(world, i + 9, j + 3, k + 0, Blocks.iron_bars, 0);
		this.setBlock(world, i + 9, j + 3, k + 3, Blocks.stonebrick, 0);
		this.setBlock(world, i + 9, j + 3, k + 12, Blocks.stonebrick, 0);
		this.setBlock(world, i + 9, j + 3, k + 15, Blocks.iron_bars, 0);
		this.setBlock(world, i + 9, j + 4, k + 0, Blocks.stonebrick, 0);
		this.setBlock(world, i + 9, j + 4, k + 3, Blocks.stonebrick, 0);
		this.setBlock(world, i + 9, j + 4, k + 4, Blocks.stonebrick, 0);
		this.setBlock(world, i + 9, j + 4, k + 5, Blocks.stonebrick, 0);
		this.setBlock(world, i + 9, j + 4, k + 6, Blocks.stonebrick, 0);
		this.setBlock(world, i + 9, j + 4, k + 7, Blocks.stonebrick, 0);
		this.setBlock(world, i + 9, j + 4, k + 8, Blocks.stonebrick, 0);
		this.setBlock(world, i + 9, j + 4, k + 9, Blocks.stonebrick, 0);
		this.setBlock(world, i + 9, j + 4, k + 10, Blocks.stonebrick, 0);
		this.setBlock(world, i + 9, j + 4, k + 11, Blocks.stonebrick, 0);
		this.setBlock(world, i + 9, j + 4, k + 12, Blocks.stonebrick, 0);
		this.setBlock(world, i + 9, j + 4, k + 15, Blocks.stonebrick, 0);
		this.setBlock(world, i + 9, j + 5, k + 3, Blocks.stonebrick, 0);
		this.setBlock(world, i + 9, j + 5, k + 12, Blocks.stonebrick, 0);
		this.setBlock(world, i + 9, j + 6, k + 3, Blocks.stonebrick, 0);
		this.setBlock(world, i + 9, j + 6, k + 12, Blocks.stonebrick, 0);
		this.setBlock(world, i + 9, j + 7, k + 3, Blocks.stonebrick, 0);
		this.setBlock(world, i + 9, j + 7, k + 12, Blocks.stonebrick, 0);
		this.setBlock(world, i + 9, j + 8, k + 3, Blocks.stonebrick, 0);
		this.setBlock(world, i + 9, j + 8, k + 4, Blocks.stonebrick, 0);
		this.setBlock(world, i + 9, j + 8, k + 5, Blocks.stonebrick, 0);
		this.setBlock(world, i + 9, j + 8, k + 6, Blocks.stonebrick, 0);
		this.setBlock(world, i + 9, j + 8, k + 7, Blocks.stonebrick, 0);
		this.setBlock(world, i + 9, j + 8, k + 8, Blocks.stonebrick, 0);
		this.setBlock(world, i + 9, j + 8, k + 9, Blocks.stonebrick, 0);
		this.setBlock(world, i + 9, j + 8, k + 10, Blocks.stonebrick, 0);
		this.setBlock(world, i + 9, j + 8, k + 11, Blocks.stonebrick, 0);
		this.setBlock(world, i + 9, j + 8, k + 12, Blocks.stonebrick, 0);
		this.setBlock(world, i + 10, j + 1, k + 0, Blocks.iron_bars, 0);
		this.setBlock(world, i + 10, j + 1, k + 3, Blocks.stonebrick, 0);
		this.setBlock(world, i + 10, j + 1, k + 12, Blocks.stonebrick, 0);
		this.setBlock(world, i + 10, j + 1, k + 15, Blocks.iron_bars, 0);
		this.setBlock(world, i + 10, j + 2, k + 0, Blocks.iron_bars, 0);
		this.setBlock(world, i + 10, j + 2, k + 3, Blocks.iron_bars, 0);
		this.setBlock(world, i + 10, j + 2, k + 12, Blocks.iron_bars, 0);
		this.setBlock(world, i + 10, j + 2, k + 15, Blocks.iron_bars, 0);
		this.setBlock(world, i + 10, j + 3, k + 0, Blocks.iron_bars, 0);
		this.setBlock(world, i + 10, j + 3, k + 3, Blocks.stonebrick, 0);
		this.setBlock(world, i + 10, j + 3, k + 12, Blocks.stonebrick, 0);
		this.setBlock(world, i + 10, j + 3, k + 15, Blocks.iron_bars, 0);
		this.setBlock(world, i + 10, j + 4, k + 0, Blocks.stonebrick, 0);
		this.setBlock(world, i + 10, j + 4, k + 3, Blocks.stonebrick, 0);
		this.setBlock(world, i + 10, j + 4, k + 4, Blocks.stonebrick, 0);
		this.setBlock(world, i + 10, j + 4, k + 5, Blocks.stonebrick, 0);
		this.setBlock(world, i + 10, j + 4, k + 6, Blocks.stonebrick, 0);
		this.setBlock(world, i + 10, j + 4, k + 7, Blocks.stonebrick, 0);
		this.setBlock(world, i + 10, j + 4, k + 8, Blocks.stonebrick, 0);
		this.setBlock(world, i + 10, j + 4, k + 9, Blocks.stonebrick, 0);
		this.setBlock(world, i + 10, j + 4, k + 10, Blocks.stonebrick, 0);
		this.setBlock(world, i + 10, j + 4, k + 11, Blocks.stonebrick, 0);
		this.setBlock(world, i + 10, j + 4, k + 12, Blocks.stonebrick, 0);
		this.setBlock(world, i + 10, j + 4, k + 15, Blocks.stonebrick, 0);
		this.setBlock(world, i + 10, j + 5, k + 3, Blocks.stonebrick, 0);
		this.setBlock(world, i + 10, j + 5, k + 12, Blocks.stonebrick, 0);
		this.setBlock(world, i + 10, j + 6, k + 3, Blocks.stonebrick, 0);
		this.setBlock(world, i + 10, j + 6, k + 12, Blocks.stonebrick, 0);
		this.setBlock(world, i + 10, j + 7, k + 3, Blocks.stonebrick, 0);
		this.setBlock(world, i + 10, j + 7, k + 12, Blocks.stonebrick, 0);
		this.setBlock(world, i + 10, j + 8, k + 3, Blocks.stonebrick, 0);
		this.setBlock(world, i + 10, j + 8, k + 4, Blocks.stonebrick, 0);
		this.setBlock(world, i + 10, j + 8, k + 5, Blocks.stonebrick, 0);
		this.setBlock(world, i + 10, j + 8, k + 6, Blocks.stonebrick, 0);
		this.setBlock(world, i + 10, j + 8, k + 7, Blocks.stonebrick, 0);
		this.setBlock(world, i + 10, j + 8, k + 8, Blocks.stonebrick, 0);
		this.setBlock(world, i + 10, j + 8, k + 9, Blocks.stonebrick, 0);
		this.setBlock(world, i + 10, j + 8, k + 10, Blocks.stonebrick, 0);
		this.setBlock(world, i + 10, j + 8, k + 11, Blocks.stonebrick, 0);
		this.setBlock(world, i + 10, j + 8, k + 12, Blocks.stonebrick, 0);
		this.setBlock(world, i + 11, j + 1, k + 0, Blocks.iron_bars, 0);
		this.setBlock(world, i + 11, j + 1, k + 3, Blocks.stonebrick, 0);
		this.setBlock(world, i + 11, j + 1, k + 4, Blocks.redstone_block, 0);
		this.setBlock(world, i + 11, j + 1, k + 9, Blocks.stonebrick, 0);
		this.setBlock(world, i + 11, j + 1, k + 11, Blocks.redstone_block, 0);
		this.setBlock(world, i + 11, j + 1, k + 12, Blocks.stonebrick, 0);
		this.setBlock(world, i + 11, j + 1, k + 15, Blocks.iron_bars, 0);
		this.setBlock(world, i + 11, j + 2, k + 0, Blocks.iron_bars, 0);
		this.setBlock(world, i + 11, j + 2, k + 3, Blocks.stonebrick, 0);
		this.setBlock(world, i + 11, j + 2, k + 4, Blocks.redstone_lamp, 0);
		this.setBlock(world, i + 11, j + 2, k + 8, Blocks.stonebrick, 0);
		this.setBlock(world, i + 11, j + 2, k + 11, Blocks.redstone_lamp, 0);
		this.setBlock(world, i + 11, j + 2, k + 12, Blocks.stonebrick, 0);
		this.setBlock(world, i + 11, j + 2, k + 15, Blocks.iron_bars, 0);
		this.setBlock(world, i + 11, j + 3, k + 0, Blocks.iron_bars, 0);
		this.setBlock(world, i + 11, j + 3, k + 3, Blocks.stonebrick, 0);
		this.setBlock(world, i + 11, j + 3, k + 7, Blocks.stonebrick, 0);
		this.setBlock(world, i + 11, j + 3, k + 12, Blocks.stonebrick, 0);
		this.setBlock(world, i + 11, j + 3, k + 15, Blocks.iron_bars, 0);
		this.setBlock(world, i + 11, j + 4, k + 0, Blocks.stonebrick, 0);
		this.setBlock(world, i + 11, j + 4, k + 3, Blocks.stonebrick, 0);
		this.setBlock(world, i + 11, j + 4, k + 4, Blocks.stonebrick, 0);
		this.setBlock(world, i + 11, j + 4, k + 5, Blocks.stonebrick, 0);
		this.setBlock(world, i + 11, j + 4, k + 6, Blocks.stonebrick, 0);
		this.setBlock(world, i + 11, j + 4, k + 10, Blocks.stonebrick, 0);
		this.setBlock(world, i + 11, j + 4, k + 11, Blocks.stonebrick, 0);
		this.setBlock(world, i + 11, j + 4, k + 12, Blocks.stonebrick, 0);
		this.setBlock(world, i + 11, j + 4, k + 15, Blocks.stonebrick, 0);
		this.setBlock(world, i + 11, j + 5, k + 3, Blocks.stonebrick, 0);
		this.setBlock(world, i + 11, j + 5, k + 4, Blocks.redstone_block, 0);
		this.setBlock(world, i + 11, j + 5, k + 11, Blocks.redstone_block, 0);
		this.setBlock(world, i + 11, j + 5, k + 12, Blocks.stonebrick, 0);
		this.setBlock(world, i + 11, j + 6, k + 3, Blocks.stonebrick, 0);
		this.setBlock(world, i + 11, j + 6, k + 4, Blocks.redstone_lamp, 0);
		this.setBlock(world, i + 11, j + 6, k + 11, Blocks.redstone_lamp, 0);
		this.setBlock(world, i + 11, j + 6, k + 12, Blocks.stonebrick, 0);
		this.setBlock(world, i + 11, j + 7, k + 3, Blocks.stonebrick, 0);
		this.setBlock(world, i + 11, j + 7, k + 12, Blocks.stonebrick, 0);
		this.setBlock(world, i + 11, j + 8, k + 3, Blocks.stonebrick, 0);
		this.setBlock(world, i + 11, j + 8, k + 4, Blocks.stonebrick, 0);
		this.setBlock(world, i + 11, j + 8, k + 5, Blocks.stonebrick, 0);
		this.setBlock(world, i + 11, j + 8, k + 6, Blocks.stonebrick, 0);
		this.setBlock(world, i + 11, j + 8, k + 7, Blocks.stonebrick, 0);
		this.setBlock(world, i + 11, j + 8, k + 8, Blocks.stonebrick, 0);
		this.setBlock(world, i + 11, j + 8, k + 9, Blocks.stonebrick, 0);
		this.setBlock(world, i + 11, j + 8, k + 10, Blocks.stonebrick, 0);
		this.setBlock(world, i + 11, j + 8, k + 11, Blocks.stonebrick, 0);
		this.setBlock(world, i + 11, j + 8, k + 12, Blocks.stonebrick, 0);
		this.setBlock(world, i + 12, j + 1, k + 0, Blocks.iron_bars, 0);
		this.setBlock(world, i + 12, j + 1, k + 3, Blocks.stonebrick, 0);
		this.setBlock(world, i + 12, j + 1, k + 4, Blocks.stonebrick, 0);
		this.setBlock(world, i + 12, j + 1, k + 5, Blocks.stonebrick, 0);
		this.setBlock(world, i + 12, j + 1, k + 6, Blocks.stonebrick, 0);
		this.setBlock(world, i + 12, j + 1, k + 7, Blocks.stonebrick, 0);
		this.setBlock(world, i + 12, j + 1, k + 8, Blocks.stonebrick, 0);
		this.setBlock(world, i + 12, j + 1, k + 9, Blocks.stonebrick, 0);
		this.setBlock(world, i + 12, j + 1, k + 10, Blocks.stonebrick, 0);
		this.setBlock(world, i + 12, j + 1, k + 11, Blocks.stonebrick, 0);
		this.setBlock(world, i + 12, j + 1, k + 12, Blocks.stonebrick, 0);
		this.setBlock(world, i + 12, j + 1, k + 15, Blocks.iron_bars, 0);
		this.setBlock(world, i + 12, j + 2, k + 0, Blocks.iron_bars, 0);
		this.setBlock(world, i + 12, j + 2, k + 3, Blocks.stonebrick, 0);
		this.setBlock(world, i + 12, j + 2, k + 4, Blocks.stonebrick, 0);
		this.setBlock(world, i + 12, j + 2, k + 5, Blocks.iron_bars, 0);
		this.setBlock(world, i + 12, j + 2, k + 6, Blocks.stonebrick, 0);
		this.setBlock(world, i + 12, j + 2, k + 7, Blocks.stonebrick, 0);
		this.setBlock(world, i + 12, j + 2, k + 8, Blocks.stonebrick, 0);
		this.setBlock(world, i + 12, j + 2, k + 9, Blocks.stonebrick, 0);
		this.setBlock(world, i + 12, j + 2, k + 10, Blocks.iron_bars, 0);
		this.setBlock(world, i + 12, j + 2, k + 11, Blocks.stonebrick, 0);
		this.setBlock(world, i + 12, j + 2, k + 12, Blocks.stonebrick, 0);
		this.setBlock(world, i + 12, j + 2, k + 15, Blocks.iron_bars, 0);
		this.setBlock(world, i + 12, j + 3, k + 0, Blocks.iron_bars, 0);
		this.setBlock(world, i + 12, j + 3, k + 3, Blocks.stonebrick, 0);
		this.setBlock(world, i + 12, j + 3, k + 4, Blocks.stonebrick, 0);
		this.setBlock(world, i + 12, j + 3, k + 5, Blocks.stonebrick, 0);
		this.setBlock(world, i + 12, j + 3, k + 6, Blocks.stonebrick, 0);
		this.setBlock(world, i + 12, j + 3, k + 7, Blocks.stonebrick, 0);
		this.setBlock(world, i + 12, j + 3, k + 8, Blocks.stonebrick, 0);
		this.setBlock(world, i + 12, j + 3, k + 9, Blocks.stonebrick, 0);
		this.setBlock(world, i + 12, j + 3, k + 10, Blocks.stonebrick, 0);
		this.setBlock(world, i + 12, j + 3, k + 11, Blocks.stonebrick, 0);
		this.setBlock(world, i + 12, j + 3, k + 12, Blocks.stonebrick, 0);
		this.setBlock(world, i + 12, j + 3, k + 15, Blocks.iron_bars, 0);
		this.setBlock(world, i + 12, j + 4, k + 0, Blocks.stonebrick, 0);
		this.setBlock(world, i + 12, j + 4, k + 3, Blocks.stonebrick, 0);
		this.setBlock(world, i + 12, j + 4, k + 4, Blocks.stonebrick, 0);
		this.setBlock(world, i + 12, j + 4, k + 5, Blocks.stonebrick, 0);
		this.setBlock(world, i + 12, j + 4, k + 6, Blocks.stonebrick, 0);
		this.setBlock(world, i + 12, j + 4, k + 7, Blocks.stonebrick, 0);
		this.setBlock(world, i + 12, j + 4, k + 8, Blocks.stonebrick, 0);
		this.setBlock(world, i + 12, j + 4, k + 9, Blocks.stonebrick, 0);
		this.setBlock(world, i + 12, j + 4, k + 10, Blocks.stonebrick, 0);
		this.setBlock(world, i + 12, j + 4, k + 11, Blocks.stonebrick, 0);
		this.setBlock(world, i + 12, j + 4, k + 12, Blocks.stonebrick, 0);
		this.setBlock(world, i + 12, j + 4, k + 15, Blocks.stonebrick, 0);
		this.setBlock(world, i + 12, j + 5, k + 3, Blocks.stonebrick, 0);
		this.setBlock(world, i + 12, j + 5, k + 4, Blocks.stonebrick, 0);
		this.setBlock(world, i + 12, j + 5, k + 5, Blocks.stonebrick, 0);
		this.setBlock(world, i + 12, j + 5, k + 6, Blocks.stonebrick, 0);
		this.setBlock(world, i + 12, j + 5, k + 7, Blocks.stonebrick, 0);
		this.setBlock(world, i + 12, j + 5, k + 8, Blocks.stonebrick, 0);
		this.setBlock(world, i + 12, j + 5, k + 9, Blocks.stonebrick, 0);
		this.setBlock(world, i + 12, j + 5, k + 10, Blocks.stonebrick, 0);
		this.setBlock(world, i + 12, j + 5, k + 11, Blocks.stonebrick, 0);
		this.setBlock(world, i + 12, j + 5, k + 12, Blocks.stonebrick, 0);
		this.setBlock(world, i + 12, j + 6, k + 3, Blocks.stonebrick, 0);
		this.setBlock(world, i + 12, j + 6, k + 4, Blocks.stonebrick, 0);
		this.setBlock(world, i + 12, j + 6, k + 5, Blocks.stonebrick, 0);
		this.setBlock(world, i + 12, j + 6, k + 6, Blocks.stonebrick, 0);
		this.setBlock(world, i + 12, j + 6, k + 7, Blocks.stonebrick, 0);
		this.setBlock(world, i + 12, j + 6, k + 8, Blocks.stonebrick, 0);
		this.setBlock(world, i + 12, j + 6, k + 9, Blocks.stonebrick, 0);
		this.setBlock(world, i + 12, j + 6, k + 10, Blocks.stonebrick, 0);
		this.setBlock(world, i + 12, j + 6, k + 11, Blocks.stonebrick, 0);
		this.setBlock(world, i + 12, j + 6, k + 12, Blocks.stonebrick, 0);
		this.setBlock(world, i + 12, j + 7, k + 3, Blocks.stonebrick, 0);
		this.setBlock(world, i + 12, j + 7, k + 4, Blocks.stonebrick, 0);
		this.setBlock(world, i + 12, j + 7, k + 5, Blocks.stonebrick, 0);
		this.setBlock(world, i + 12, j + 7, k + 6, Blocks.stonebrick, 0);
		this.setBlock(world, i + 12, j + 7, k + 7, Blocks.stonebrick, 0);
		this.setBlock(world, i + 12, j + 7, k + 8, Blocks.stonebrick, 0);
		this.setBlock(world, i + 12, j + 7, k + 9, Blocks.stonebrick, 0);
		this.setBlock(world, i + 12, j + 7, k + 10, Blocks.stonebrick, 0);
		this.setBlock(world, i + 12, j + 7, k + 11, Blocks.stonebrick, 0);
		this.setBlock(world, i + 12, j + 7, k + 12, Blocks.stonebrick, 0);
		this.setBlock(world, i + 12, j + 8, k + 3, Blocks.stonebrick, 0);
		this.setBlock(world, i + 12, j + 8, k + 4, Blocks.stonebrick, 0);
		this.setBlock(world, i + 12, j + 8, k + 5, Blocks.stonebrick, 0);
		this.setBlock(world, i + 12, j + 8, k + 6, Blocks.stonebrick, 0);
		this.setBlock(world, i + 12, j + 8, k + 7, Blocks.stonebrick, 0);
		this.setBlock(world, i + 12, j + 8, k + 8, Blocks.stonebrick, 0);
		this.setBlock(world, i + 12, j + 8, k + 9, Blocks.stonebrick, 0);
		this.setBlock(world, i + 12, j + 8, k + 10, Blocks.stonebrick, 0);
		this.setBlock(world, i + 12, j + 8, k + 11, Blocks.stonebrick, 0);
		this.setBlock(world, i + 12, j + 8, k + 12, Blocks.stonebrick, 0);
		this.setBlock(world, i + 13, j + 1, k + 0, Blocks.iron_bars, 0);
		this.setBlock(world, i + 13, j + 1, k + 15, Blocks.iron_bars, 0);
		this.setBlock(world, i + 13, j + 2, k + 0, Blocks.iron_bars, 0);
		this.setBlock(world, i + 13, j + 2, k + 15, Blocks.iron_bars, 0);
		this.setBlock(world, i + 13, j + 3, k + 0, Blocks.iron_bars, 0);
		this.setBlock(world, i + 13, j + 3, k + 15, Blocks.iron_bars, 0);
		this.setBlock(world, i + 13, j + 4, k + 0, Blocks.stonebrick, 0);
		this.setBlock(world, i + 13, j + 4, k + 15, Blocks.stonebrick, 0);
		this.setBlock(world, i + 14, j + 1, k + 0, Blocks.iron_bars, 0);
		this.setBlock(world, i + 14, j + 1, k + 15, Blocks.iron_bars, 0);
		this.setBlock(world, i + 14, j + 2, k + 0, Blocks.iron_bars, 0);
		this.setBlock(world, i + 14, j + 2, k + 15, Blocks.iron_bars, 0);
		this.setBlock(world, i + 14, j + 3, k + 0, Blocks.iron_bars, 0);
		this.setBlock(world, i + 14, j + 3, k + 15, Blocks.iron_bars, 0);
		this.setBlock(world, i + 14, j + 4, k + 0, Blocks.stonebrick, 0);
		this.setBlock(world, i + 14, j + 4, k + 15, Blocks.stonebrick, 0);
		this.setBlock(world, i + 14, j + 11, k + 0, Blocks.glowstone, 0);
		this.setBlock(world, i + 14, j + 11, k + 1, Blocks.stonebrick, 0);
		this.setBlock(world, i + 14, j + 11, k + 14, Blocks.glowstone, 0);
		this.setBlock(world, i + 14, j + 11, k + 15, Blocks.stonebrick, 0);
		this.setBlock(world, i + 15, j + 1, k + 0, Blocks.stonebrick, 0);
		this.setBlock(world, i + 15, j + 1, k + 1, Blocks.iron_bars, 0);
		this.setBlock(world, i + 15, j + 1, k + 2, Blocks.iron_bars, 0);
		this.setBlock(world, i + 15, j + 1, k + 3, Blocks.iron_bars, 0);
		this.setBlock(world, i + 15, j + 1, k + 4, Blocks.iron_bars, 0);
		this.setBlock(world, i + 15, j + 1, k + 5, Blocks.iron_bars, 0);
		this.setBlock(world, i + 15, j + 1, k + 6, Blocks.iron_bars, 0);
		this.setBlock(world, i + 15, j + 1, k + 7, Blocks.iron_bars, 0);
		this.setBlock(world, i + 15, j + 1, k + 8, Blocks.iron_bars, 0);
		this.setBlock(world, i + 15, j + 1, k + 9, Blocks.iron_bars, 0);
		this.setBlock(world, i + 15, j + 1, k + 10, Blocks.iron_bars, 0);
		this.setBlock(world, i + 15, j + 1, k + 11, Blocks.iron_bars, 0);
		this.setBlock(world, i + 15, j + 1, k + 12, Blocks.iron_bars, 0);
		this.setBlock(world, i + 15, j + 1, k + 13, Blocks.iron_bars, 0);
		this.setBlock(world, i + 15, j + 1, k + 14, Blocks.iron_bars, 0);
		this.setBlock(world, i + 15, j + 1, k + 15, Blocks.stonebrick, 0);
		this.setBlock(world, i + 15, j + 2, k + 0, Blocks.stonebrick, 0);
		this.setBlock(world, i + 15, j + 2, k + 1, Blocks.iron_bars, 0);
		this.setBlock(world, i + 15, j + 2, k + 2, Blocks.iron_bars, 0);
		this.setBlock(world, i + 15, j + 2, k + 3, Blocks.iron_bars, 0);
		this.setBlock(world, i + 15, j + 2, k + 4, Blocks.iron_bars, 0);
		this.setBlock(world, i + 15, j + 2, k + 5, Blocks.iron_bars, 0);
		this.setBlock(world, i + 15, j + 2, k + 6, Blocks.iron_bars, 0);
		this.setBlock(world, i + 15, j + 2, k + 7, Blocks.iron_bars, 0);
		this.setBlock(world, i + 15, j + 2, k + 8, Blocks.iron_bars, 0);
		this.setBlock(world, i + 15, j + 2, k + 9, Blocks.iron_bars, 0);
		this.setBlock(world, i + 15, j + 2, k + 10, Blocks.iron_bars, 0);
		this.setBlock(world, i + 15, j + 2, k + 11, Blocks.iron_bars, 0);
		this.setBlock(world, i + 15, j + 2, k + 12, Blocks.iron_bars, 0);
		this.setBlock(world, i + 15, j + 2, k + 13, Blocks.iron_bars, 0);
		this.setBlock(world, i + 15, j + 2, k + 14, Blocks.iron_bars, 0);
		this.setBlock(world, i + 15, j + 2, k + 15, Blocks.stonebrick, 0);
		this.setBlock(world, i + 15, j + 3, k + 0, Blocks.stonebrick, 0);
		this.setBlock(world, i + 15, j + 3, k + 1, Blocks.iron_bars, 0);
		this.setBlock(world, i + 15, j + 3, k + 2, Blocks.iron_bars, 0);
		this.setBlock(world, i + 15, j + 3, k + 3, Blocks.iron_bars, 0);
		this.setBlock(world, i + 15, j + 3, k + 4, Blocks.iron_bars, 0);
		this.setBlock(world, i + 15, j + 3, k + 5, Blocks.iron_bars, 0);
		this.setBlock(world, i + 15, j + 3, k + 6, Blocks.iron_bars, 0);
		this.setBlock(world, i + 15, j + 3, k + 7, Blocks.iron_bars, 0);
		this.setBlock(world, i + 15, j + 3, k + 8, Blocks.iron_bars, 0);
		this.setBlock(world, i + 15, j + 3, k + 9, Blocks.iron_bars, 0);
		this.setBlock(world, i + 15, j + 3, k + 10, Blocks.iron_bars, 0);
		this.setBlock(world, i + 15, j + 3, k + 11, Blocks.iron_bars, 0);
		this.setBlock(world, i + 15, j + 3, k + 12, Blocks.iron_bars, 0);
		this.setBlock(world, i + 15, j + 3, k + 13, Blocks.iron_bars, 0);
		this.setBlock(world, i + 15, j + 3, k + 14, Blocks.iron_bars, 0);
		this.setBlock(world, i + 15, j + 3, k + 15, Blocks.stonebrick, 0);
		this.setBlock(world, i + 15, j + 4, k + 0, Blocks.stonebrick, 0);
		this.setBlock(world, i + 15, j + 4, k + 1, Blocks.stonebrick, 0);
		this.setBlock(world, i + 15, j + 4, k + 2, Blocks.stonebrick, 0);
		this.setBlock(world, i + 15, j + 4, k + 3, Blocks.stonebrick, 0);
		this.setBlock(world, i + 15, j + 4, k + 4, Blocks.stonebrick, 0);
		this.setBlock(world, i + 15, j + 4, k + 5, Blocks.stonebrick, 0);
		this.setBlock(world, i + 15, j + 4, k + 6, Blocks.stonebrick, 0);
		this.setBlock(world, i + 15, j + 4, k + 7, Blocks.stonebrick, 0);
		this.setBlock(world, i + 15, j + 4, k + 8, Blocks.stonebrick, 0);
		this.setBlock(world, i + 15, j + 4, k + 9, Blocks.stonebrick, 0);
		this.setBlock(world, i + 15, j + 4, k + 10, Blocks.stonebrick, 0);
		this.setBlock(world, i + 15, j + 4, k + 11, Blocks.stonebrick, 0);
		this.setBlock(world, i + 15, j + 4, k + 12, Blocks.stonebrick, 0);
		this.setBlock(world, i + 15, j + 4, k + 13, Blocks.stonebrick, 0);
		this.setBlock(world, i + 15, j + 4, k + 14, Blocks.stonebrick, 0);
		this.setBlock(world, i + 15, j + 4, k + 15, Blocks.stonebrick, 0);
		this.setBlock(world, i + 15, j + 5, k + 0, Blocks.stonebrick, 0);
		this.setBlock(world, i + 15, j + 5, k + 15, Blocks.stonebrick, 0);
		this.setBlock(world, i + 15, j + 6, k + 0, Blocks.stonebrick, 0);
		this.setBlock(world, i + 15, j + 6, k + 15, Blocks.stonebrick, 0);
		this.setBlock(world, i + 15, j + 7, k + 0, Blocks.stonebrick, 0);
		this.setBlock(world, i + 15, j + 7, k + 15, Blocks.stonebrick, 0);
		this.setBlock(world, i + 15, j + 8, k + 0, Blocks.stonebrick, 0);
		this.setBlock(world, i + 15, j + 8, k + 15, Blocks.stonebrick, 0);
		this.setBlock(world, i + 15, j + 9, k + 0, Blocks.stonebrick, 0);
		this.setBlock(world, i + 15, j + 9, k + 15, Blocks.stonebrick, 0);
		this.setBlock(world, i + 15, j + 10, k + 0, Blocks.stonebrick, 0);
		this.setBlock(world, i + 15, j + 10, k + 15, Blocks.stonebrick, 0);
		this.setBlock(world, i + 15, j + 11, k + 0, Blocks.stonebrick, 0);
		this.setBlock(world, i + 15, j + 11, k + 1, Blocks.stonebrick, 0);
		this.setBlock(world, i + 15, j + 11, k + 14, Blocks.stonebrick, 0);
		this.setBlock(world, i + 15, j + 11, k + 15, Blocks.stonebrick, 0);
		this.setBlock(world, i + 0, j + 0, k + 0, Blocks.gravel, 0);
		this.setBlock(world, i + 0, j + 0, k + 1, Blocks.gravel, 0);
		this.setBlock(world, i + 0, j + 0, k + 2, Blocks.gravel, 0);
		this.setBlock(world, i + 0, j + 0, k + 3, Blocks.gravel, 0);
		this.setBlock(world, i + 0, j + 0, k + 4, Blocks.gravel, 0);
		this.setBlock(world, i + 0, j + 0, k + 5, Blocks.gravel, 0);
		this.setBlock(world, i + 0, j + 0, k + 6, Blocks.gravel, 0);
		this.setBlock(world, i + 0, j + 0, k + 7, Blocks.gravel, 0);
		this.setBlock(world, i + 0, j + 0, k + 8, Blocks.gravel, 0);
		this.setBlock(world, i + 0, j + 0, k + 9, Blocks.gravel, 0);
		this.setBlock(world, i + 0, j + 0, k + 10, Blocks.gravel, 0);
		this.setBlock(world, i + 0, j + 0, k + 11, Blocks.gravel, 0);
		this.setBlock(world, i + 0, j + 0, k + 12, Blocks.gravel, 0);
		this.setBlock(world, i + 0, j + 0, k + 13, Blocks.gravel, 0);
		this.setBlock(world, i + 0, j + 0, k + 14, Blocks.gravel, 0);
		this.setBlock(world, i + 0, j + 0, k + 15, Blocks.gravel, 0);
		this.setBlock(world, i + 1, j + 0, k + 0, Blocks.gravel, 0);
		this.setBlock(world, i + 1, j + 0, k + 1, Blocks.gravel, 0);
		this.setBlock(world, i + 1, j + 0, k + 2, Blocks.gravel, 0);
		this.setBlock(world, i + 1, j + 0, k + 3, Blocks.gravel, 0);
		this.setBlock(world, i + 1, j + 0, k + 4, Blocks.gravel, 0);
		this.setBlock(world, i + 1, j + 0, k + 5, Blocks.gravel, 0);
		this.setBlock(world, i + 1, j + 0, k + 6, Blocks.gravel, 0);
		this.setBlock(world, i + 1, j + 0, k + 7, Blocks.gravel, 0);
		this.setBlock(world, i + 1, j + 0, k + 8, Blocks.gravel, 0);
		this.setBlock(world, i + 1, j + 0, k + 9, Blocks.gravel, 0);
		this.setBlock(world, i + 1, j + 0, k + 10, Blocks.gravel, 0);
		this.setBlock(world, i + 1, j + 0, k + 11, Blocks.gravel, 0);
		this.setBlock(world, i + 1, j + 0, k + 12, Blocks.gravel, 0);
		this.setBlock(world, i + 1, j + 0, k + 13, Blocks.gravel, 0);
		this.setBlock(world, i + 1, j + 0, k + 14, Blocks.gravel, 0);
		this.setBlock(world, i + 1, j + 0, k + 15, Blocks.gravel, 0);
		this.setBlock(world, i + 2, j + 0, k + 0, Blocks.gravel, 0);
		this.setBlock(world, i + 2, j + 0, k + 1, Blocks.gravel, 0);
		this.setBlock(world, i + 2, j + 0, k + 2, Blocks.gravel, 0);
		this.setBlock(world, i + 2, j + 0, k + 3, Blocks.gravel, 0);
		this.setBlock(world, i + 2, j + 0, k + 4, Blocks.gravel, 0);
		this.setBlock(world, i + 2, j + 0, k + 5, Blocks.gravel, 0);
		this.setBlock(world, i + 2, j + 0, k + 6, Blocks.gravel, 0);
		this.setBlock(world, i + 2, j + 0, k + 7, Blocks.gravel, 0);
		this.setBlock(world, i + 2, j + 0, k + 8, Blocks.gravel, 0);
		this.setBlock(world, i + 2, j + 0, k + 9, Blocks.gravel, 0);
		this.setBlock(world, i + 2, j + 0, k + 10, Blocks.gravel, 0);
		this.setBlock(world, i + 2, j + 0, k + 11, Blocks.gravel, 0);
		this.setBlock(world, i + 2, j + 0, k + 12, Blocks.gravel, 0);
		this.setBlock(world, i + 2, j + 0, k + 13, Blocks.gravel, 0);
		this.setBlock(world, i + 2, j + 0, k + 14, Blocks.gravel, 0);
		this.setBlock(world, i + 2, j + 0, k + 15, Blocks.gravel, 0);
		this.setBlock(world, i + 3, j + 0, k + 0, Blocks.gravel, 0);
		this.setBlock(world, i + 3, j + 0, k + 1, Blocks.gravel, 0);
		this.setBlock(world, i + 3, j + 0, k + 2, Blocks.gravel, 0);
		this.setBlock(world, i + 3, j + 0, k + 3, Blocks.gravel, 0);
		this.setBlock(world, i + 3, j + 0, k + 4, Blocks.gravel, 0);
		this.setBlock(world, i + 3, j + 0, k + 5, Blocks.gravel, 0);
		this.setBlock(world, i + 3, j + 0, k + 6, Blocks.gravel, 0);
		this.setBlock(world, i + 3, j + 0, k + 7, Blocks.gravel, 0);
		this.setBlock(world, i + 3, j + 0, k + 8, Blocks.gravel, 0);
		this.setBlock(world, i + 3, j + 0, k + 9, Blocks.gravel, 0);
		this.setBlock(world, i + 3, j + 0, k + 10, Blocks.gravel, 0);
		this.setBlock(world, i + 3, j + 0, k + 11, Blocks.gravel, 0);
		this.setBlock(world, i + 3, j + 0, k + 12, Blocks.gravel, 0);
		this.setBlock(world, i + 3, j + 0, k + 13, Blocks.gravel, 0);
		this.setBlock(world, i + 3, j + 0, k + 14, Blocks.gravel, 0);
		this.setBlock(world, i + 3, j + 0, k + 15, Blocks.gravel, 0);
		this.setBlock(world, i + 4, j + 0, k + 0, Blocks.gravel, 0);
		this.setBlock(world, i + 4, j + 0, k + 1, Blocks.gravel, 0);
		this.setBlock(world, i + 4, j + 0, k + 2, Blocks.gravel, 0);
		this.setBlock(world, i + 4, j + 0, k + 3, Blocks.gravel, 0);
		this.setBlock(world, i + 4, j + 0, k + 4, Blocks.gravel, 0);
		this.setBlock(world, i + 4, j + 0, k + 5, Blocks.gravel, 0);
		this.setBlock(world, i + 4, j + 0, k + 6, Blocks.gravel, 0);
		this.setBlock(world, i + 4, j + 0, k + 7, Blocks.gravel, 0);
		this.setBlock(world, i + 4, j + 0, k + 8, Blocks.gravel, 0);
		this.setBlock(world, i + 4, j + 0, k + 9, Blocks.gravel, 0);
		this.setBlock(world, i + 4, j + 0, k + 10, Blocks.gravel, 0);
		this.setBlock(world, i + 4, j + 0, k + 11, Blocks.gravel, 0);
		this.setBlock(world, i + 4, j + 0, k + 12, Blocks.gravel, 0);
		this.setBlock(world, i + 4, j + 0, k + 13, Blocks.gravel, 0);
		this.setBlock(world, i + 4, j + 0, k + 14, Blocks.gravel, 0);
		this.setBlock(world, i + 4, j + 0, k + 15, Blocks.gravel, 0);
		this.setBlock(world, i + 5, j + 0, k + 0, Blocks.gravel, 0);
		this.setBlock(world, i + 5, j + 0, k + 1, Blocks.gravel, 0);
		this.setBlock(world, i + 5, j + 0, k + 2, Blocks.gravel, 0);
		this.setBlock(world, i + 5, j + 0, k + 3, Blocks.gravel, 0);
		this.setBlock(world, i + 5, j + 0, k + 4, Blocks.gravel, 0);
		this.setBlock(world, i + 5, j + 0, k + 5, Blocks.gravel, 0);
		this.setBlock(world, i + 5, j + 0, k + 6, Blocks.gravel, 0);
		this.setBlock(world, i + 5, j + 0, k + 7, Blocks.gravel, 0);
		this.setBlock(world, i + 5, j + 0, k + 8, Blocks.gravel, 0);
		this.setBlock(world, i + 5, j + 0, k + 9, Blocks.gravel, 0);
		this.setBlock(world, i + 5, j + 0, k + 10, Blocks.gravel, 0);
		this.setBlock(world, i + 5, j + 0, k + 11, Blocks.gravel, 0);
		this.setBlock(world, i + 5, j + 0, k + 12, Blocks.gravel, 0);
		this.setBlock(world, i + 5, j + 0, k + 13, Blocks.gravel, 0);
		this.setBlock(world, i + 5, j + 0, k + 14, Blocks.gravel, 0);
		this.setBlock(world, i + 5, j + 0, k + 15, Blocks.gravel, 0);
		this.setBlock(world, i + 6, j + 0, k + 0, Blocks.gravel, 0);
		this.setBlock(world, i + 6, j + 0, k + 1, Blocks.gravel, 0);
		this.setBlock(world, i + 6, j + 0, k + 2, Blocks.gravel, 0);
		this.setBlock(world, i + 6, j + 0, k + 3, Blocks.gravel, 0);
		this.setBlock(world, i + 6, j + 0, k + 4, Blocks.gravel, 0);
		this.setBlock(world, i + 6, j + 0, k + 5, Blocks.gravel, 0);
		this.setBlock(world, i + 6, j + 0, k + 6, Blocks.gravel, 0);
		this.setBlock(world, i + 6, j + 0, k + 7, Blocks.gravel, 0);
		this.setBlock(world, i + 6, j + 0, k + 8, Blocks.gravel, 0);
		this.setBlock(world, i + 6, j + 0, k + 9, Blocks.gravel, 0);
		this.setBlock(world, i + 6, j + 0, k + 10, Blocks.gravel, 0);
		this.setBlock(world, i + 6, j + 0, k + 11, Blocks.gravel, 0);
		this.setBlock(world, i + 6, j + 0, k + 12, Blocks.gravel, 0);
		this.setBlock(world, i + 6, j + 0, k + 13, Blocks.gravel, 0);
		this.setBlock(world, i + 6, j + 0, k + 14, Blocks.gravel, 0);
		this.setBlock(world, i + 6, j + 0, k + 15, Blocks.gravel, 0);
		this.setBlock(world, i + 7, j + 0, k + 0, Blocks.gravel, 0);
		this.setBlock(world, i + 7, j + 0, k + 1, Blocks.gravel, 0);
		this.setBlock(world, i + 7, j + 0, k + 2, Blocks.gravel, 0);
		this.setBlock(world, i + 7, j + 0, k + 3, Blocks.gravel, 0);
		this.setBlock(world, i + 7, j + 0, k + 4, Blocks.gravel, 0);
		this.setBlock(world, i + 7, j + 0, k + 5, Blocks.gravel, 0);
		this.setBlock(world, i + 7, j + 0, k + 6, Blocks.gravel, 0);
		this.setBlock(world, i + 7, j + 0, k + 7, Blocks.gravel, 0);
		this.setBlock(world, i + 7, j + 0, k + 8, Blocks.gravel, 0);
		this.setBlock(world, i + 7, j + 0, k + 9, Blocks.gravel, 0);
		this.setBlock(world, i + 7, j + 0, k + 10, Blocks.gravel, 0);
		this.setBlock(world, i + 7, j + 0, k + 11, Blocks.gravel, 0);
		this.setBlock(world, i + 7, j + 0, k + 12, Blocks.gravel, 0);
		this.setBlock(world, i + 7, j + 0, k + 13, Blocks.gravel, 0);
		this.setBlock(world, i + 7, j + 0, k + 14, Blocks.gravel, 0);
		this.setBlock(world, i + 7, j + 0, k + 15, Blocks.gravel, 0);
		this.setBlock(world, i + 8, j + 0, k + 0, Blocks.gravel, 0);
		this.setBlock(world, i + 8, j + 0, k + 1, Blocks.gravel, 0);
		this.setBlock(world, i + 8, j + 0, k + 2, Blocks.gravel, 0);
		this.setBlock(world, i + 8, j + 0, k + 3, Blocks.gravel, 0);
		this.setBlock(world, i + 8, j + 0, k + 4, Blocks.gravel, 0);
		this.setBlock(world, i + 8, j + 0, k + 5, Blocks.gravel, 0);
		this.setBlock(world, i + 8, j + 0, k + 6, Blocks.gravel, 0);
		this.setBlock(world, i + 8, j + 0, k + 7, Blocks.gravel, 0);
		this.setBlock(world, i + 8, j + 0, k + 8, Blocks.gravel, 0);
		this.setBlock(world, i + 8, j + 0, k + 9, Blocks.gravel, 0);
		this.setBlock(world, i + 8, j + 0, k + 10, Blocks.gravel, 0);
		this.setBlock(world, i + 8, j + 0, k + 11, Blocks.gravel, 0);
		this.setBlock(world, i + 8, j + 0, k + 12, Blocks.gravel, 0);
		this.setBlock(world, i + 8, j + 0, k + 13, Blocks.gravel, 0);
		this.setBlock(world, i + 8, j + 0, k + 14, Blocks.gravel, 0);
		this.setBlock(world, i + 8, j + 0, k + 15, Blocks.gravel, 0);
		this.setBlock(world, i + 9, j + 0, k + 0, Blocks.gravel, 0);
		this.setBlock(world, i + 9, j + 0, k + 1, Blocks.gravel, 0);
		this.setBlock(world, i + 9, j + 0, k + 2, Blocks.gravel, 0);
		this.setBlock(world, i + 9, j + 0, k + 3, Blocks.gravel, 0);
		this.setBlock(world, i + 9, j + 0, k + 4, Blocks.gravel, 0);
		this.setBlock(world, i + 9, j + 0, k + 5, Blocks.gravel, 0);
		this.setBlock(world, i + 9, j + 0, k + 6, Blocks.gravel, 0);
		this.setBlock(world, i + 9, j + 0, k + 7, Blocks.gravel, 0);
		this.setBlock(world, i + 9, j + 0, k + 8, Blocks.gravel, 0);
		this.setBlock(world, i + 9, j + 0, k + 9, Blocks.gravel, 0);
		this.setBlock(world, i + 9, j + 0, k + 10, Blocks.gravel, 0);
		this.setBlock(world, i + 9, j + 0, k + 11, Blocks.gravel, 0);
		this.setBlock(world, i + 9, j + 0, k + 12, Blocks.gravel, 0);
		this.setBlock(world, i + 9, j + 0, k + 13, Blocks.gravel, 0);
		this.setBlock(world, i + 9, j + 0, k + 14, Blocks.gravel, 0);
		this.setBlock(world, i + 9, j + 0, k + 15, Blocks.gravel, 0);
		this.setBlock(world, i + 10, j + 0, k + 0, Blocks.gravel, 0);
		this.setBlock(world, i + 10, j + 0, k + 1, Blocks.gravel, 0);
		this.setBlock(world, i + 10, j + 0, k + 2, Blocks.gravel, 0);
		this.setBlock(world, i + 10, j + 0, k + 3, Blocks.gravel, 0);
		this.setBlock(world, i + 10, j + 0, k + 4, Blocks.gravel, 0);
		this.setBlock(world, i + 10, j + 0, k + 5, Blocks.gravel, 0);
		this.setBlock(world, i + 10, j + 0, k + 6, Blocks.gravel, 0);
		this.setBlock(world, i + 10, j + 0, k + 7, Blocks.gravel, 0);
		this.setBlock(world, i + 10, j + 0, k + 8, Blocks.gravel, 0);
		this.setBlock(world, i + 10, j + 0, k + 9, Blocks.gravel, 0);
		this.setBlock(world, i + 10, j + 0, k + 10, Blocks.gravel, 0);
		this.setBlock(world, i + 10, j + 0, k + 11, Blocks.gravel, 0);
		this.setBlock(world, i + 10, j + 0, k + 12, Blocks.gravel, 0);
		this.setBlock(world, i + 10, j + 0, k + 13, Blocks.gravel, 0);
		this.setBlock(world, i + 10, j + 0, k + 14, Blocks.gravel, 0);
		this.setBlock(world, i + 10, j + 0, k + 15, Blocks.gravel, 0);
		this.setBlock(world, i + 11, j + 0, k + 0, Blocks.gravel, 0);
		this.setBlock(world, i + 11, j + 0, k + 1, Blocks.gravel, 0);
		this.setBlock(world, i + 11, j + 0, k + 2, Blocks.gravel, 0);
		this.setBlock(world, i + 11, j + 0, k + 3, Blocks.gravel, 0);
		this.setBlock(world, i + 11, j + 0, k + 4, Blocks.gravel, 0);
		this.setBlock(world, i + 11, j + 0, k + 5, Blocks.gravel, 0);
		this.setBlock(world, i + 11, j + 0, k + 6, Blocks.gravel, 0);
		this.setBlock(world, i + 11, j + 0, k + 7, Blocks.gravel, 0);
		this.setBlock(world, i + 11, j + 0, k + 8, Blocks.gravel, 0);
		this.setBlock(world, i + 11, j + 0, k + 9, Blocks.gravel, 0);
		this.setBlock(world, i + 11, j + 0, k + 10, Blocks.gravel, 0);
		this.setBlock(world, i + 11, j + 0, k + 11, Blocks.gravel, 0);
		this.setBlock(world, i + 11, j + 0, k + 12, Blocks.gravel, 0);
		this.setBlock(world, i + 11, j + 0, k + 13, Blocks.gravel, 0);
		this.setBlock(world, i + 11, j + 0, k + 14, Blocks.gravel, 0);
		this.setBlock(world, i + 11, j + 0, k + 15, Blocks.gravel, 0);
		this.setBlock(world, i + 12, j + 0, k + 0, Blocks.gravel, 0);
		this.setBlock(world, i + 12, j + 0, k + 1, Blocks.gravel, 0);
		this.setBlock(world, i + 12, j + 0, k + 2, Blocks.gravel, 0);
		this.setBlock(world, i + 12, j + 0, k + 3, Blocks.gravel, 0);
		this.setBlock(world, i + 12, j + 0, k + 4, Blocks.gravel, 0);
		this.setBlock(world, i + 12, j + 0, k + 5, Blocks.gravel, 0);
		this.setBlock(world, i + 12, j + 0, k + 6, Blocks.gravel, 0);
		this.setBlock(world, i + 12, j + 0, k + 7, Blocks.gravel, 0);
		this.setBlock(world, i + 12, j + 0, k + 8, Blocks.gravel, 0);
		this.setBlock(world, i + 12, j + 0, k + 9, Blocks.gravel, 0);
		this.setBlock(world, i + 12, j + 0, k + 10, Blocks.gravel, 0);
		this.setBlock(world, i + 12, j + 0, k + 11, Blocks.gravel, 0);
		this.setBlock(world, i + 12, j + 0, k + 12, Blocks.gravel, 0);
		this.setBlock(world, i + 12, j + 0, k + 13, Blocks.gravel, 0);
		this.setBlock(world, i + 12, j + 0, k + 14, Blocks.gravel, 0);
		this.setBlock(world, i + 12, j + 0, k + 15, Blocks.gravel, 0);
		this.setBlock(world, i + 13, j + 0, k + 0, Blocks.gravel, 0);
		this.setBlock(world, i + 13, j + 0, k + 1, Blocks.gravel, 0);
		this.setBlock(world, i + 13, j + 0, k + 2, Blocks.gravel, 0);
		this.setBlock(world, i + 13, j + 0, k + 3, Blocks.gravel, 0);
		this.setBlock(world, i + 13, j + 0, k + 4, Blocks.gravel, 0);
		this.setBlock(world, i + 13, j + 0, k + 5, Blocks.gravel, 0);
		this.setBlock(world, i + 13, j + 0, k + 6, Blocks.gravel, 0);
		this.setBlock(world, i + 13, j + 0, k + 7, Blocks.gravel, 0);
		this.setBlock(world, i + 13, j + 0, k + 8, Blocks.gravel, 0);
		this.setBlock(world, i + 13, j + 0, k + 9, Blocks.gravel, 0);
		this.setBlock(world, i + 13, j + 0, k + 10, Blocks.gravel, 0);
		this.setBlock(world, i + 13, j + 0, k + 11, Blocks.gravel, 0);
		this.setBlock(world, i + 13, j + 0, k + 12, Blocks.gravel, 0);
		this.setBlock(world, i + 13, j + 0, k + 13, Blocks.gravel, 0);
		this.setBlock(world, i + 13, j + 0, k + 14, Blocks.gravel, 0);
		this.setBlock(world, i + 13, j + 0, k + 15, Blocks.gravel, 0);
		this.setBlock(world, i + 14, j + 0, k + 0, Blocks.gravel, 0);
		this.setBlock(world, i + 14, j + 0, k + 1, Blocks.gravel, 0);
		this.setBlock(world, i + 14, j + 0, k + 2, Blocks.gravel, 0);
		this.setBlock(world, i + 14, j + 0, k + 3, Blocks.gravel, 0);
		this.setBlock(world, i + 14, j + 0, k + 4, Blocks.gravel, 0);
		this.setBlock(world, i + 14, j + 0, k + 5, Blocks.gravel, 0);
		this.setBlock(world, i + 14, j + 0, k + 6, Blocks.gravel, 0);
		this.setBlock(world, i + 14, j + 0, k + 7, Blocks.gravel, 0);
		this.setBlock(world, i + 14, j + 0, k + 8, Blocks.gravel, 0);
		this.setBlock(world, i + 14, j + 0, k + 9, Blocks.gravel, 0);
		this.setBlock(world, i + 14, j + 0, k + 10, Blocks.gravel, 0);
		this.setBlock(world, i + 14, j + 0, k + 11, Blocks.gravel, 0);
		this.setBlock(world, i + 14, j + 0, k + 12, Blocks.gravel, 0);
		this.setBlock(world, i + 14, j + 0, k + 13, Blocks.gravel, 0);
		this.setBlock(world, i + 14, j + 0, k + 14, Blocks.gravel, 0);
		this.setBlock(world, i + 14, j + 0, k + 15, Blocks.gravel, 0);
		this.setBlock(world, i + 15, j + 0, k + 0, Blocks.gravel, 0);
		this.setBlock(world, i + 15, j + 0, k + 1, Blocks.gravel, 0);
		this.setBlock(world, i + 15, j + 0, k + 2, Blocks.gravel, 0);
		this.setBlock(world, i + 15, j + 0, k + 3, Blocks.gravel, 0);
		this.setBlock(world, i + 15, j + 0, k + 4, Blocks.gravel, 0);
		this.setBlock(world, i + 15, j + 0, k + 5, Blocks.gravel, 0);
		this.setBlock(world, i + 15, j + 0, k + 6, Blocks.gravel, 0);
		this.setBlock(world, i + 15, j + 0, k + 7, Blocks.gravel, 0);
		this.setBlock(world, i + 15, j + 0, k + 8, Blocks.gravel, 0);
		this.setBlock(world, i + 15, j + 0, k + 9, Blocks.gravel, 0);
		this.setBlock(world, i + 15, j + 0, k + 10, Blocks.gravel, 0);
		this.setBlock(world, i + 15, j + 0, k + 11, Blocks.gravel, 0);
		this.setBlock(world, i + 15, j + 0, k + 12, Blocks.gravel, 0);
		this.setBlock(world, i + 15, j + 0, k + 13, Blocks.gravel, 0);
		this.setBlock(world, i + 15, j + 0, k + 14, Blocks.gravel, 0);
		this.setBlock(world, i + 15, j + 0, k + 15, Blocks.gravel, 0);
		for (int x = i; x < i+16; x++){
			for (int z = k; z < k+16; z++){
				this.setBlock(world, x, j-1, z, Blocks.dirt, 0);
			}
		}

		return true;
	}
	public void generateSurvivorStiltsHouse(World world, Random rand, int i, int j, int k){
		this.setBlock(world, i + 0, j + 0, k + 0, Blocks.planks, 0);
		this.setBlock(world, i + 0, j + 0, k + 1, Blocks.planks, 0);
		this.setBlock(world, i + 0, j + 0, k + 2, Blocks.planks, 0);
		this.setBlock(world, i + 0, j + 0, k + 3, Blocks.planks, 0);
		this.setBlock(world, i + 0, j + 0, k + 4, Blocks.planks, 0);
		this.setBlock(world, i + 0, j + 0, k + 5, Blocks.planks, 0);
		this.setBlock(world, i + 0, j + 1, k + 0, Blocks.log, 0);
		this.setBlock(world, i + 0, j + 1, k + 1, Blocks.planks, 0);
		this.setBlock(world, i + 0, j + 1, k + 2, Blocks.planks, 0);
		this.setBlock(world, i + 0, j + 1, k + 3, Blocks.planks, 0);
		this.setBlock(world, i + 0, j + 1, k + 4, Blocks.planks, 0);
		this.setBlock(world, i + 0, j + 1, k + 5, Blocks.log, 0);
		this.setBlock(world, i + 0, j + 2, k + 0, Blocks.log, 0);
		this.setBlock(world, i + 0, j + 2, k + 1, Blocks.planks, 0);
		this.setBlock(world, i + 0, j + 2, k + 2, Blocks.planks, 0);
		this.setBlock(world, i + 0, j + 2, k + 3, Blocks.planks, 0);
		this.setBlock(world, i + 0, j + 2, k + 4, Blocks.planks, 0);
		this.setBlock(world, i + 0, j + 2, k + 5, Blocks.log, 0);
		this.setBlock(world, i + 0, j + 3, k + 0, Blocks.planks, 0);
		this.setBlock(world, i + 0, j + 3, k + 1, Blocks.planks, 0);
		this.setBlock(world, i + 0, j + 3, k + 2, Blocks.planks, 0);
		this.setBlock(world, i + 0, j + 3, k + 3, Blocks.planks, 0);
		this.setBlock(world, i + 0, j + 3, k + 4, Blocks.planks, 0);
		this.setBlock(world, i + 0, j + 3, k + 5, Blocks.planks, 0);
		this.setBlock(world, i + 1, j + 0, k + 0, Blocks.planks, 0);
		this.setBlock(world, i + 1, j + 0, k + 1, Blocks.planks, 0);
		this.setBlock(world, i + 1, j + 0, k + 2, Blocks.planks, 0);
		this.setBlock(world, i + 1, j + 0, k + 3, Blocks.planks, 0);
		this.setBlock(world, i + 1, j + 0, k + 4, Blocks.planks, 0);
		this.setBlock(world, i + 1, j + 0, k + 5, Blocks.planks, 0);
		this.setBlock(world, i + 1, j + 1, k + 0, Blocks.planks, 0);
		this.setBlock(world, i + 1, j + 1, k + 4, Blocks.glowstone, 0);
		this.setBlock(world, i + 1, j + 1, k + 5, Blocks.planks, 0);
		this.setBlock(world, i + 1, j + 2, k + 0, Blocks.planks, 0);
		this.setBlock(world, i + 1, j + 2, k + 5, Blocks.planks, 0);
		this.setBlock(world, i + 1, j + 3, k + 0, Blocks.planks, 0);
		this.setBlock(world, i + 1, j + 3, k + 1, Blocks.planks, 0);
		this.setBlock(world, i + 1, j + 3, k + 2, Blocks.planks, 0);
		this.setBlock(world, i + 1, j + 3, k + 3, Blocks.planks, 0);
		this.setBlock(world, i + 1, j + 3, k + 4, Blocks.planks, 0);
		this.setBlock(world, i + 1, j + 3, k + 5, Blocks.planks, 0);
		this.setBlock(world, i + 2, j + 0, k + 0, Blocks.planks, 0);
		this.setBlock(world, i + 2, j + 0, k + 1, Blocks.planks, 0);
		this.setBlock(world, i + 2, j + 0, k + 2, Blocks.planks, 0);
		this.setBlock(world, i + 2, j + 0, k + 3, Blocks.planks, 0);
		this.setBlock(world, i + 2, j + 0, k + 4, Blocks.planks, 0);
		this.setBlock(world, i + 2, j + 0, k + 5, Blocks.planks, 0);
		this.setBlock(world, i + 2, j + 1, k + 0, Blocks.planks, 0);
		this.setBlock(world, i + 2, j + 1, k + 4, Blocks.furnace, 2);
		this.setBlock(world, i + 2, j + 1, k + 5, Blocks.planks, 0);
		this.setBlock(world, i + 2, j + 2, k + 0, Blocks.planks, 0);
		this.setBlock(world, i + 2, j + 2, k + 5, Blocks.planks, 0);
		this.setBlock(world, i + 2, j + 3, k + 0, Blocks.planks, 0);
		this.setBlock(world, i + 2, j + 3, k + 1, Blocks.planks, 0);
		this.setBlock(world, i + 2, j + 3, k + 2, Blocks.planks, 0);
		this.setBlock(world, i + 2, j + 3, k + 3, Blocks.planks, 0);
		this.setBlock(world, i + 2, j + 3, k + 4, Blocks.planks, 0);
		this.setBlock(world, i + 2, j + 3, k + 5, Blocks.planks, 0);
		this.setBlock(world, i + 3, j + 0, k + 0, Blocks.planks, 0);
		this.setBlock(world, i + 3, j + 0, k + 1, Blocks.planks, 0);
		this.setBlock(world, i + 3, j + 0, k + 2, Blocks.planks, 0);
		this.setBlock(world, i + 3, j + 0, k + 3, Blocks.planks, 0);
		this.setBlock(world, i + 3, j + 0, k + 4, Blocks.planks, 0);
		this.setBlock(world, i + 3, j + 0, k + 5, Blocks.planks, 0);
		this.setBlock(world, i + 3, j + 1, k + 4, Blocks.crafting_table, 0);
		this.setBlock(world, i + 3, j + 1, k + 5, Blocks.planks, 0);
		this.setBlock(world, i + 3, j + 2, k + 5, Blocks.planks, 0);
		this.setBlock(world, i + 3, j + 3, k + 0, Blocks.planks, 0);
		this.setBlock(world, i + 3, j + 3, k + 1, Blocks.planks, 0);
		this.setBlock(world, i + 3, j + 3, k + 2, Blocks.planks, 0);
		this.setBlock(world, i + 3, j + 3, k + 3, Blocks.planks, 0);
		this.setBlock(world, i + 3, j + 3, k + 4, Blocks.planks, 0);
		this.setBlock(world, i + 3, j + 3, k + 5, Blocks.planks, 0);
		this.setBlock(world, i + 4, j + 0, k + 0, Blocks.planks, 0);
		this.setBlock(world, i + 4, j + 0, k + 1, Blocks.planks, 0);
		this.setBlock(world, i + 4, j + 0, k + 2, Blocks.planks, 0);
		this.setBlock(world, i + 4, j + 0, k + 3, Blocks.planks, 0);
		this.setBlock(world, i + 4, j + 0, k + 4, Blocks.planks, 0);
		this.setBlock(world, i + 4, j + 0, k + 5, Blocks.planks, 0);
		this.setBlock(world, i + 4, j + 1, k + 0, Blocks.planks, 0);
		this.setBlock(world, i + 4, j + 1, k + 4, Blocks.chest, 2);
		TileEntityChest chest = (TileEntityChest)world.getTileEntity(new BlockPos(i + 4, j + 1, k + 4));
		chest.setInventorySlotContents(0, ((ItemBackpack)ZombieApocalypse.backpack).fillWithRandom(FillType.STILT_HOUSE));
		
		this.setBlock(world, i + 4, j + 1, k + 5, Blocks.planks, 0);
		this.setBlock(world, i + 4, j + 2, k + 0, Blocks.planks, 0);
		this.setBlock(world, i + 4, j + 2, k + 5, Blocks.planks, 0);
		this.setBlock(world, i + 4, j + 3, k + 0, Blocks.planks, 0);
		this.setBlock(world, i + 4, j + 3, k + 1, Blocks.planks, 0);
		this.setBlock(world, i + 4, j + 3, k + 2, Blocks.planks, 0);
		this.setBlock(world, i + 4, j + 3, k + 3, Blocks.planks, 0);
		this.setBlock(world, i + 4, j + 3, k + 4, Blocks.planks, 0);
		this.setBlock(world, i + 4, j + 3, k + 5, Blocks.planks, 0);
		this.setBlock(world, i + 5, j + 0, k + 0, Blocks.planks, 0);
		this.setBlock(world, i + 5, j + 0, k + 1, Blocks.planks, 0);
		this.setBlock(world, i + 5, j + 0, k + 2, Blocks.planks, 0);
		this.setBlock(world, i + 5, j + 0, k + 3, Blocks.planks, 0);
		this.setBlock(world, i + 5, j + 0, k + 4, Blocks.planks, 0);
		this.setBlock(world, i + 5, j + 0, k + 5, Blocks.planks, 0);
		this.setBlock(world, i + 5, j + 1, k + 0, Blocks.log, 0);
		this.setBlock(world, i + 5, j + 1, k + 1, Blocks.planks, 0);
		this.setBlock(world, i + 5, j + 1, k + 2, Blocks.planks, 0);
		this.setBlock(world, i + 5, j + 1, k + 3, Blocks.planks, 0);
		this.setBlock(world, i + 5, j + 1, k + 4, Blocks.planks, 0);
		this.setBlock(world, i + 5, j + 1, k + 5, Blocks.log, 0);
		this.setBlock(world, i + 5, j + 2, k + 0, Blocks.log, 0);
		this.setBlock(world, i + 5, j + 2, k + 1, Blocks.planks, 0);
		this.setBlock(world, i + 5, j + 2, k + 2, Blocks.planks, 0);
		this.setBlock(world, i + 5, j + 2, k + 3, Blocks.planks, 0);
		this.setBlock(world, i + 5, j + 2, k + 4, Blocks.planks, 0);
		this.setBlock(world, i + 5, j + 2, k + 5, Blocks.log, 0);
		this.setBlock(world, i + 5, j + 3, k + 0, Blocks.planks, 0);
		this.setBlock(world, i + 5, j + 3, k + 1, Blocks.planks, 0);
		this.setBlock(world, i + 5, j + 3, k + 2, Blocks.planks, 0);
		this.setBlock(world, i + 5, j + 3, k + 3, Blocks.planks, 0);
		this.setBlock(world, i + 5, j + 3, k + 4, Blocks.planks, 0);
		this.setBlock(world, i + 5, j + 3, k + 5, Blocks.planks, 0);
	}
	public void generateCity(World world, Random rand, int i, int j, int k, CityBuildingType building){
		if (building == CityBuildingType.HOUSE){
			this.setBlock(world, i + 0, j + 0, k + 0, Blocks.brick_block, 0);
			this.setBlock(world, i + 0, j + 0, k + 1, Blocks.brick_block, 0);
			this.setBlock(world, i + 0, j + 0, k + 2, Blocks.brick_block, 0);
			this.setBlock(world, i + 0, j + 0, k + 3, Blocks.brick_block, 0);
			this.setBlock(world, i + 0, j + 0, k + 4, Blocks.brick_block, 0);
			this.setBlock(world, i + 0, j + 0, k + 5, Blocks.brick_block, 0);
			this.setBlock(world, i + 0, j + 1, k + 0, Blocks.brick_block, 0);
			this.setBlock(world, i + 0, j + 1, k + 1, Blocks.brick_block, 0);
			this.setBlock(world, i + 0, j + 1, k + 2, Blocks.brick_block, 0);
			this.setBlock(world, i + 0, j + 1, k + 3, Blocks.brick_block, 0);
			this.setBlock(world, i + 0, j + 1, k + 4, Blocks.brick_block, 0);
			this.setBlock(world, i + 0, j + 1, k + 5, Blocks.brick_block, 0);
			this.setBlock(world, i + 0, j + 2, k + 0, Blocks.brick_block, 0);
			this.setBlock(world, i + 0, j + 2, k + 1, Blocks.brick_block, 0);
			this.setBlock(world, i + 0, j + 2, k + 2, Blocks.brick_block, 0);
			this.setBlock(world, i + 0, j + 2, k + 3, Blocks.brick_block, 0);
			this.setBlock(world, i + 0, j + 2, k + 4, Blocks.brick_block, 0);
			this.setBlock(world, i + 0, j + 2, k + 5, Blocks.brick_block, 0);
			this.setBlock(world, i + 0, j + 3, k + 0, Blocks.brick_block, 0);
			this.setBlock(world, i + 0, j + 3, k + 1, Blocks.brick_block, 0);
			this.setBlock(world, i + 0, j + 3, k + 2, Blocks.brick_block, 0);
			this.setBlock(world, i + 0, j + 3, k + 3, Blocks.brick_block, 0);
			this.setBlock(world, i + 0, j + 3, k + 4, Blocks.brick_block, 0);
			this.setBlock(world, i + 0, j + 3, k + 5, Blocks.brick_block, 0);
			this.setBlock(world, i + 1, j + 0, k + 0, Blocks.brick_block, 0);
			this.setBlock(world, i + 1, j + 0, k + 1, Blocks.brick_block, 0);
			this.setBlock(world, i + 1, j + 0, k + 2, Blocks.brick_block, 0);
			this.setBlock(world, i + 1, j + 0, k + 3, Blocks.brick_block, 0);
			this.setBlock(world, i + 1, j + 0, k + 4, Blocks.brick_block, 0);
			this.setBlock(world, i + 1, j + 0, k + 5, Blocks.brick_block, 0);
			this.setBlock(world, i + 1, j + 1, k + 0, Blocks.brick_block, 0);
			this.setBlock(world, i + 1, j + 1, k + 1, Blocks.chest, 3);
			TileEntityChest chest = (TileEntityChest)world.getTileEntity(new BlockPos(i + 1, j + 1, k + 1));
			chest.setInventorySlotContents(0, ((ItemBackpack)ZombieApocalypse.backpack).fillWithRandom(FillType.ARMORED_HOUSE));
			
			
			this.setBlock(world, i + 1, j + 1, k + 5, Blocks.brick_block, 0);
			this.setBlock(world, i + 1, j + 2, k + 0, Blocks.brick_block, 0);
			this.setBlock(world, i + 1, j + 2, k + 5, Blocks.brick_block, 0);
			this.setBlock(world, i + 1, j + 3, k + 0, Blocks.brick_block, 0);
			this.setBlock(world, i + 1, j + 3, k + 5, Blocks.brick_block, 0);
			this.setBlock(world, i + 1, j + 4, k + 1, Blocks.brick_block, 0);
